<robot name="drone">

<gazebo>
  <plugin name="aero_plugin" filename="libaero_plugin.so">
  </plugin>
</gazebo>

<gazebo>
  <plugin name="control_plugin" filename="libcontrol_plugin.so">
  </plugin>
</gazebo>

<gazebo>
<plugin name="gazebo_ros_control" filename="libgazebo_ros_control.so">
<robotNamespace>/drone</robotNamespace>
</plugin>
</gazebo>

<gazebo>
<plugin name="drone_internal_imu_plugin" filename="libhector_gazebo_ros_imu.so" >
    <alwaysOn>true</alwaysOn>
    <bodyName>base_link</bodyName>
    <frameName>base_link</frameName>
    <topicName>IMU/imu_data</topicName>
    <serviceName>drone/internal_sensors/imu_service</serviceName>
    <updateRate>100.0</updateRate>
    <gaussianNoise>0.001</gaussianNoise>
    <!-- accelerometer params -->
    <accelOffset>0.0 0.0 0.0</accelOffset>
    <accelGaussianNoise>0.0003 0.0003 0.0003</accelGaussianNoise>
    <accelDrift>0.00004 0.00004 0.00004</accelDrift>
    <accelFrequency>0.0025 0.0025 0.0025</accelFrequency>
    <!-- gyroscope params -->
    <rateOffset>0.0 0.0 0.0</rateOffset>
    <rateDrift>0.01 0.01 0.01</rateDrift>
    <rateDriftFrequency>0.001 0.001 0.001</rateDriftFrequency>
    <rateGaussianNoise>0.01 0.01 0.01</rateGaussianNoise>
</plugin>
</gazebo>

<gazebo>
   <plugin name="drone_internal_magnetic_sim" filename="libhector_gazebo_ros_magnetic.so">
     <updateRate>100.0</updateRate>
     <bodyName>base_link</bodyName>
     <frameId>base_link</frameId>
     <topicName>MAGNET/magnetic_data</topicName>
     <offset>0 0 0</offset>
     <drift>0.0 0.0 0.0</drift>
     <gaussianNoise>1.3e-3 1.3e-3 1.3e-3</gaussianNoise>
   </plugin>
 </gazebo>

 <gazebo>
     <plugin name="drone_internal_gps_sim" filename="libhector_gazebo_ros_gps.so">
       <updateRate>4.0</updateRate>
       <bodyName>base_link</bodyName>
       <frameId>base_link</frameId>
       <topicName>GPS/fix</topicName>
       <velocityTopicName>GPS/fix_velocity</velocityTopicName>
       <referenceLatitude>49.860246</referenceLatitude>
       <referenceLongitude>8.687077</referenceLongitude>
       <drift>0.0 0.0 0.0</drift>
       <gaussianNoise>0.01 0.01 0.01</gaussianNoise>
       <velocityDrift>0 0 0</velocityDrift>
       <velocityGaussianNoise>0.01 0.01 0.01</velocityGaussianNoise>
     </plugin>
   </gazebo>

   <!-- camera -->
  <gazebo reference="base_link">
    <sensor type="camera" name="camera1">
      <update_rate>30.0</update_rate>
      <camera name="head">
        <vertical_fov>3.1415926</vertical_fov>
        <image>
          <width>800</width>
          <height>800</height>
          <format>R8G8B8</format>
        </image>
        <clip>
          <near>0.02</near>
          <far>300</far>
        </clip>
        <noise>
          <type>gaussian</type>
          <!-- Noise is sampled independently per pixel on each frame.
               That pixel's noise value is added to each of its color
               channels, which at that point lie in the range [0,1]. -->
          <mean>0.0</mean>
          <stddev>0.007</stddev>
        </noise>
      </camera>
      <plugin name="camera_controller" filename="libgazebo_ros_camera.so">
        <alwaysOn>true</alwaysOn>
        <updateRate>0.0</updateRate>
        <cameraName>camera1</cameraName>
        <imageTopicName>image_raw</imageTopicName>
        <cameraInfoTopicName>camera_info</cameraInfoTopicName>
        <frameName>base_link</frameName>
        <hackBaseline>0.07</hackBaseline>
        <distortionK1>0.0</distortionK1>
        <distortionK2>0.0</distortionK2>
        <distortionK3>0.0</distortionK3>
        <distortionT1>0.0</distortionT1>
        <distortionT2>0.0</distortionT2>
      </plugin>
    </sensor>
  </gazebo>
  <link
    name="base_link">
    <inertial>
      <origin
        xyz="7.2098E-07 -2.0914E-07 0.11714"
        rpy="0 0 0" />
      <mass
        value="10.223" />
      <inertia
        ixx="0.39298"
        ixy="-5.4134E-07"
        ixz="-5.281E-08"
        iyy="0.39298"
        iyz="-1.1492E-07"
        izz="0.77449" />
    </inertial>
    <visual>
      <origin
        xyz="0 0 0"
        rpy="0 0 0" />
      <geometry>
        <mesh
          filename="package://flypulator_description/meshes/base_link.STL" />
      </geometry>
      <material
        name="">
        <color
          rgba="1 1 1 1" />
      </material>
    </visual>
    <collision>
      <origin
        xyz="0 0 0"
        rpy="0 0 0" />
      <geometry>
        <mesh
          filename="package://flypulator_description/meshes/base_link.STL" />
      </geometry>
    </collision>
  </link>
  <link
    name="motor_Link1">
    <inertial>
      <origin
        xyz="0.00053889 -2.7756E-17 0.029473"
        rpy="0 0 0" />
      <mass
        value="0.082637" />
      <inertia
        ixx="3.0939E-05"
        ixy="-5.0822E-21"
        ixz="6.445E-07"
        iyy="2.7112E-05"
        iyz="8.0468E-21"
        izz="8.0573E-06" />
    </inertial>
    <visual>
      <origin
        xyz="0 0 0"
        rpy="0 0 0" />
      <geometry>
        <mesh
          filename="package://flypulator_description/meshes/motor_Link1.STL" />
      </geometry>
      <material
        name="">
        <color
          rgba="0.89804 0.91765 0.92941 1" />
      </material>
    </visual>
    <collision>
      <origin
        xyz="0 0 0"
        rpy="0 0 0" />
      <geometry>
        <mesh
          filename="package://flypulator_description/meshes/motor_Link1.STL" />
      </geometry>
    </collision>
  </link>
  <joint
    name="motor_joint1"
    type="fixed">
    <origin
      xyz="-0.27069 -0.44763 0.11439"
      rpy="0.7854 0 1.0472" />
    <parent
      link="base_link" />
    <child
      link="motor_Link1" />
    <axis
      xyz="0 0 0" />
  </joint>
  <link
    name="blade_Link1">
    <inertial>
      <origin
        xyz="0 -5.5511E-17 7.2446E-06"
        rpy="0 0 0" />
      <mass
        value="0.02171" />
      <inertia
        ixx="0.00015037"
        ixy="-3.8388E-05"
        ixz="-5.421E-20"
        iyy="1.0581E-05"
        iyz="-2.287E-19"
        izz="0.00016094" />
    </inertial>
    <visual>
      <origin
        xyz="0 0 0"
        rpy="0 0 0" />
      <geometry>
        <mesh
          filename="package://flypulator_description/meshes/blade_Link1.STL" />
      </geometry>
      <material
        name="">
        <color
          rgba="1 1 1 1" />
      </material>
    </visual>
    <collision>
      <origin
        xyz="0 0 0"
        rpy="0 0 0" />
      <geometry>
        <mesh
          filename="package://flypulator_description/meshes/blade_Link1.STL" />
      </geometry>
    </collision>
  </link>
  <joint
    name="blade_joint1"
    type="continuous">
    <origin
      xyz="0 0 0.063"
      rpy="8.3267E-17 0 -1.1102E-16" />
    <parent
      link="motor_Link1" />
    <child
      link="blade_Link1" />
    <axis
      xyz="0 0 1" />
  </joint>
  <link
    name="motor_Link2">
    <inertial>
      <origin
        xyz="-0.00053889 -5.5511E-17 0.029473"
        rpy="0 0 0" />
      <mass
        value="0.082637" />
      <inertia
        ixx="3.0939E-05"
        ixy="6.7763E-21"
        ixz="-6.445E-07"
        iyy="2.7112E-05"
        iyz="4.0234E-21"
        izz="8.0573E-06" />
    </inertial>
    <visual>
      <origin
        xyz="0 0 0"
        rpy="0 0 0" />
      <geometry>
        <mesh
          filename="package://flypulator_description/meshes/motor_Link2.STL" />
      </geometry>
      <material
        name="">
        <color
          rgba="0.89804 0.91765 0.92941 1" />
      </material>
    </visual>
    <collision>
      <origin
        xyz="0 0 0"
        rpy="0 0 0" />
      <geometry>
        <mesh
          filename="package://flypulator_description/meshes/motor_Link2.STL" />
      </geometry>
    </collision>
  </link>
  <joint
    name="motor_joint2"
    type="fixed">
    <origin
      xyz="0.27069 -0.44763 0.11439"
      rpy="0.7854 0 -1.0472" />
    <parent
      link="base_link" />
    <child
      link="motor_Link2" />
    <axis
      xyz="0 0 0" />
  </joint>
  <link
    name="blade_Link2">
    <inertial>
      <origin
        xyz="0 2.7756E-17 7.2446E-06"
        rpy="0 0 0" />
      <mass
        value="0.02171" />
      <inertia
        ixx="7.3254E-05"
        ixy="7.9416E-05"
        ixz="-7.708E-20"
        iyy="8.7699E-05"
        iyz="5.1669E-20"
        izz="0.00016094" />
    </inertial>
    <visual>
      <origin
        xyz="0 0 0"
        rpy="0 0 0" />
      <geometry>
        <mesh
          filename="package://flypulator_description/meshes/blade_Link2.STL" />
      </geometry>
      <material
        name="">
        <color
          rgba="1 1 1 1" />
      </material>
    </visual>
    <collision>
      <origin
        xyz="0 0 0"
        rpy="0 0 0" />
      <geometry>
        <mesh
          filename="package://flypulator_description/meshes/blade_Link2.STL" />
      </geometry>
    </collision>
  </link>
  <joint
    name="blade_joint2"
    type="continuous">
    <origin
      xyz="0 0 0.063"
      rpy="-1.3878E-17 0 0" />
    <parent
      link="motor_Link2" />
    <child
      link="blade_Link2" />
    <axis
      xyz="0 0 1" />
  </joint>
  <link
    name="motor_Link3">
    <inertial>
      <origin
        xyz="0.00053889 -1.3878E-17 0.029473"
        rpy="0 0 0" />
      <mass
        value="0.082637" />
      <inertia
        ixx="3.0939E-05"
        ixy="5.8234E-22"
        ixz="6.445E-07"
        iyy="2.7112E-05"
        iyz="-5.9292E-21"
        izz="8.0573E-06" />
    </inertial>
    <visual>
      <origin
        xyz="0 0 0"
        rpy="0 0 0" />
      <geometry>
        <mesh
          filename="package://flypulator_description/meshes/motor_Link3.STL" />
      </geometry>
      <material
        name="">
        <color
          rgba="0.89804 0.91765 0.92941 1" />
      </material>
    </visual>
    <collision>
      <origin
        xyz="0 0 0"
        rpy="0 0 0" />
      <geometry>
        <mesh
          filename="package://flypulator_description/meshes/motor_Link3.STL" />
      </geometry>
    </collision>
  </link>
  <joint
    name="motor_joint3"
    type="fixed">
    <origin
      xyz="0.523 -0.010607 0.11439"
      rpy="0.7854 0 3.1416" />
    <parent
      link="base_link" />
    <child
      link="motor_Link3" />
    <axis
      xyz="0 0 0" />
  </joint>
  <link
    name="blade_Link3">
    <inertial>
      <origin
        xyz="0 -1.3878E-17 7.2446E-06"
        rpy="0 0 0" />
      <mass
        value="0.02171" />
      <inertia
        ixx="0.00014768"
        ixy="4.2933E-05"
        ixz="2.7105E-20"
        iyy="1.3276E-05"
        iyz="-6.9457E-20"
        izz="0.00016094" />
    </inertial>
    <visual>
      <origin
        xyz="0 0 0"
        rpy="0 0 0" />
      <geometry>
        <mesh
          filename="package://flypulator_description/meshes/blade_Link3.STL" />
      </geometry>
      <material
        name="">
        <color
          rgba="1 1 1 1" />
      </material>
    </visual>
    <collision>
      <origin
        xyz="0 0 0"
        rpy="0 0 0" />
      <geometry>
        <mesh
          filename="package://flypulator_description/meshes/blade_Link3.STL" />
      </geometry>
    </collision>
  </link>
  <joint
    name="blade_joint3"
    type="continuous">
    <origin
      xyz="0 0 0.063"
      rpy="0 0 0" />
    <parent
      link="motor_Link3" />
    <child
      link="blade_Link3" />
    <axis
      xyz="0 0 1" />
  </joint>
  <link
    name="motor_Link4">
    <inertial>
      <origin
        xyz="-0.00053889 -8.3267E-17 0.029473"
        rpy="0 0 0" />
      <mass
        value="0.082637" />
      <inertia
        ixx="3.0939E-05"
        ixy="-3.3881E-21"
        ixz="-6.445E-07"
        iyy="2.7112E-05"
        iyz="6.2469E-21"
        izz="8.0573E-06" />
    </inertial>
    <visual>
      <origin
        xyz="0 0 0"
        rpy="0 0 0" />
      <geometry>
        <mesh
          filename="package://flypulator_description/meshes/motor_Link4.STL" />
      </geometry>
      <material
        name="">
        <color
          rgba="0.89804 0.91765 0.92941 1" />
      </material>
    </visual>
    <collision>
      <origin
        xyz="0 0 0"
        rpy="0 0 0" />
      <geometry>
        <mesh
          filename="package://flypulator_description/meshes/motor_Link4.STL" />
      </geometry>
    </collision>
  </link>
  <joint
    name="motor_joint4"
    type="fixed">
    <origin
      xyz="0.25231 0.45823 0.11439"
      rpy="0.7854 0 1.0472" />
    <parent
      link="base_link" />
    <child
      link="motor_Link4" />
    <axis
      xyz="0 0 0" />
  </joint>
  <link
    name="blade_Link4">
    <inertial>
      <origin
        xyz="2.2204E-16 -5.6899E-16 7.2446E-06"
        rpy="0 0 0" />
      <mass
        value="0.02171" />
      <inertia
        ixx="0.00015683"
        ixy="2.3E-05"
        ixz="-2.0329E-20"
        iyy="4.1213E-06"
        iyz="1.135E-19"
        izz="0.00016094" />
    </inertial>
    <visual>
      <origin
        xyz="0 0 0"
        rpy="0 0 0" />
      <geometry>
        <mesh
          filename="package://flypulator_description/meshes/blade_Link4.STL" />
      </geometry>
      <material
        name="">
        <color
          rgba="1 1 1 1" />
      </material>
    </visual>
    <collision>
      <origin
        xyz="0 0 0"
        rpy="0 0 0" />
      <geometry>
        <mesh
          filename="package://flypulator_description/meshes/blade_Link4.STL" />
      </geometry>
    </collision>
  </link>
  <joint
    name="blade_joint4"
    type="continuous">
    <origin
      xyz="0 0 0.063"
      rpy="-8.3267E-17 0 -1.1102E-16" />
    <parent
      link="motor_Link4" />
    <child
      link="blade_Link4" />
    <axis
      xyz="0 0 1" />
  </joint>
  <link
    name="motor_Link5">
    <inertial>
      <origin
        xyz="0.00053889 1.3878E-17 0.029473"
        rpy="0 0 0" />
      <mass
        value="0.082637" />
      <inertia
        ixx="3.0939E-05"
        ixy="2.5411E-21"
        ixz="6.445E-07"
        iyy="2.7112E-05"
        iyz="-6.988E-21"
        izz="8.0573E-06" />
    </inertial>
    <visual>
      <origin
        xyz="0 0 0"
        rpy="0 0 0" />
      <geometry>
        <mesh
          filename="package://flypulator_description/meshes/motor_Link5.STL" />
      </geometry>
      <material
        name="">
        <color
          rgba="0.89804 0.91765 0.92941 1" />
      </material>
    </visual>
    <collision>
      <origin
        xyz="0 0 0"
        rpy="0 0 0" />
      <geometry>
        <mesh
          filename="package://flypulator_description/meshes/motor_Link5.STL" />
      </geometry>
    </collision>
  </link>
  <joint
    name="motor_joint5"
    type="fixed">
    <origin
      xyz="-0.25231 0.45823 0.11439"
      rpy="0.7854 0 -1.0472" />
    <parent
      link="base_link" />
    <child
      link="motor_Link5" />
    <axis
      xyz="0 0 0" />
  </joint>
  <link
    name="blade_Link5">
    <inertial>
      <origin
        xyz="-1.1102E-16 1.8041E-16 7.2446E-06"
        rpy="0 0 0" />
      <mass
        value="0.02171" />
      <inertia
        ixx="7.5383E-05"
        ixy="7.9581E-05"
        ixz="-7.0304E-20"
        iyy="8.557E-05"
        iyz="5.3363E-20"
        izz="0.00016094" />
    </inertial>
    <visual>
      <origin
        xyz="0 0 0"
        rpy="0 0 0" />
      <geometry>
        <mesh
          filename="package://flypulator_description/meshes/blade_Link5.STL" />
      </geometry>
      <material
        name="">
        <color
          rgba="1 1 1 1" />
      </material>
    </visual>
    <collision>
      <origin
        xyz="0 0 0"
        rpy="0 0 0" />
      <geometry>
        <mesh
          filename="package://flypulator_description/meshes/blade_Link5.STL" />
      </geometry>
    </collision>
  </link>
  <joint
    name="blade_joint5"
    type="continuous">
    <origin
      xyz="0 0 0.063"
      rpy="0 0 5.5511E-17" />
    <parent
      link="motor_Link5" />
    <child
      link="blade_Link5" />
    <axis
      xyz="0 0 1" />
  </joint>
  <link
    name="motor_Link6">
    <inertial>
      <origin
        xyz="-0.00053889 0 0.029473"
        rpy="0 0 0" />
      <mass
        value="0.082637" />
      <inertia
        ixx="3.0939E-05"
        ixy="-3.7058E-22"
        ixz="-6.445E-07"
        iyy="2.7112E-05"
        iyz="-1.6941E-21"
        izz="8.0573E-06" />
    </inertial>
    <visual>
      <origin
        xyz="0 0 0"
        rpy="0 0 0" />
      <geometry>
        <mesh
          filename="package://flypulator_description/meshes/motor_Link6.STL" />
      </geometry>
      <material
        name="">
        <color
          rgba="0.89804 0.91765 0.92941 1" />
      </material>
    </visual>
    <collision>
      <origin
        xyz="0 0 0"
        rpy="0 0 0" />
      <geometry>
        <mesh
          filename="package://flypulator_description/meshes/motor_Link6.STL" />
      </geometry>
    </collision>
  </link>
  <joint
    name="motor_joint6"
    type="fixed">
    <origin
      xyz="-0.523 -0.010607 0.11439"
      rpy="0.7854 0 3.1416" />
    <parent
      link="base_link" />
    <child
      link="motor_Link6" />
    <axis
      xyz="0 0 0" />
  </joint>
  <link
    name="blade_Link6">
    <inertial>
      <origin
        xyz="1.1102E-16 4.1633E-17 7.2446E-06"
        rpy="0 0 0" />
      <mass
        value="0.02171" />
      <inertia
        ixx="9.7974E-05"
        ixy="7.7801E-05"
        ixz="-8.8091E-20"
        iyy="6.2979E-05"
        iyz="1.152E-19"
        izz="0.00016094" />
    </inertial>
    <visual>
      <origin
        xyz="0 0 0"
        rpy="0 0 0" />
      <geometry>
        <mesh
          filename="package://flypulator_description/meshes/blade_Link6.STL" />
      </geometry>
      <material
        name="">
        <color
          rgba="1 1 1 1" />
      </material>
    </visual>
    <collision>
      <origin
        xyz="0 0 0"
        rpy="0 0 0" />
      <geometry>
        <mesh
          filename="package://flypulator_description/meshes/blade_Link6.STL" />
      </geometry>
    </collision>
  </link>
  <joint
    name="blade_joint6"
    type="continuous">
    <origin
      xyz="0 0 0.063"
      rpy="0 0 0" />
    <parent
      link="motor_Link6" />
    <child
      link="blade_Link6" />
    <axis
      xyz="0 0 1" />
  </joint>
<transmission name="tran1">
    <type>transmission_interface/SimpleTransmission</type>
    <joint name="blade_joint1">
    <hardwareInterface>EffortJointInterface</hardwareInterface>
    </joint>
    <actuator name="motor1">
      <hardwareInterface>EffortJointInterface</hardwareInterface>
      <mechanicalReduction>1</mechanicalReduction>
    </actuator>
  </transmission>
  <transmission name="tran2">
    <type>transmission_interface/SimpleTransmission</type>
    <joint name="blade_joint2">
      <hardwareInterface>EffortJointInterface</hardwareInterface>
    </joint>
    <actuator name="motor2">
      <hardwareInterface>EffortJointInterface</hardwareInterface>
      <mechanicalReduction>1</mechanicalReduction>
    </actuator>
  </transmission>
  <transmission name="tran3">
    <type>transmission_interface/SimpleTransmission</type>
    <joint name="blade_joint3">
      <hardwareInterface>EffortJointInterface</hardwareInterface>
    </joint>
    <actuator name="motor3">
      <hardwareInterface>EffortJointInterface</hardwareInterface>
      <mechanicalReduction>1</mechanicalReduction>
    </actuator>
  </transmission>
  <transmission name="tran4">
    <type>transmission_interface/SimpleTransmission</type>
    <joint name="blade_joint4">
      <hardwareInterface>EffortJointInterface</hardwareInterface>
    </joint>
    <actuator name="motor4">
      <hardwareInterface>EffortJointInterface</hardwareInterface>
      <mechanicalReduction>1</mechanicalReduction>
    </actuator>
  </transmission>
  <transmission name="tran5">
    <type>transmission_interface/SimpleTransmission</type>
    <joint name="blade_joint5">
      <hardwareInterface>EffortJointInterface</hardwareInterface>
    </joint>
    <actuator name="motor5">
      <hardwareInterface>EffortJointInterface</hardwareInterface>
      <mechanicalReduction>1</mechanicalReduction>
    </actuator>
  </transmission>
  <transmission name="tran6">
    <type>transmission_interface/SimpleTransmission</type>
    <joint name="blade_joint6">
      <hardwareInterface>EffortJointInterface</hardwareInterface>
    </joint>
    <actuator name="motor6">
      <hardwareInterface>EffortJointInterface</hardwareInterface>
      <mechanicalReduction>1</mechanicalReduction>
    </actuator>
  </transmission>

</robot>
