<?xml version="1.0"?>
<robot
  name="drone">
  
  <gazebo>
    <plugin name="aero_plugin" filename="libaero_plugin.so">
    </plugin>
  </gazebo>

  <gazebo>
    <plugin name="control_plugin" filename="libcontrol_plugin.so">
    </plugin>
  </gazebo>

  <gazebo>
    <plugin name="fake_sensor_plugin" filename="libfake_sensor_plugin.so">
    </plugin>
  </gazebo>

  <gazebo>
    <plugin name="gazebo_ros_control" filename="libgazebo_ros_control.so">
      <robotNamespace>/drone</robotNamespace>
    </plugin>
  </gazebo>

  <gazebo>
    <plugin name="drone_internal_imu_plugin" filename="libhector_gazebo_ros_imu.so" >
      <alwaysOn>true</alwaysOn>
      <bodyName>base_link</bodyName>
      <frameName>base_link</frameName>
      <topicName>IMU/imu_data</topicName>
      <serviceName>drone/internal_sensors/imu_service</serviceName>
      <updateRate>100.0</updateRate>
      <gaussianNoise>0.001</gaussianNoise>
      <!-- accelerometer params -->
      <accelOffset>0.0 0.0 0.0</accelOffset>
      <accelGaussianNoise>0.0003 0.0003 0.0003</accelGaussianNoise>
      <accelDrift>0.00004 0.00004 0.00004</accelDrift>
      <accelFrequency>0.0025 0.0025 0.0025</accelFrequency>
      <!-- gyroscope params -->
      <rateOffset>0.0 0.0 0.0</rateOffset>
      <rateDrift>0.01 0.01 0.01</rateDrift>
      <rateDriftFrequency>0.001 0.001 0.001</rateDriftFrequency>
      <rateGaussianNoise>0.01 0.01 0.01</rateGaussianNoise>
    </plugin>
  </gazebo>

  <gazebo>
    <plugin name="drone_internal_magnetic_sim" filename="libhector_gazebo_ros_magnetic.so">
      <updateRate>100.0</updateRate>
      <bodyName>base_link</bodyName>
      <frameId>base_link</frameId>
      <topicName>MAGNET/magnetic_data</topicName>
      <offset>0 0 0</offset>
      <drift>0.0 0.0 0.0</drift>
      <gaussianNoise>1.3e-3 1.3e-3 1.3e-3</gaussianNoise>
    </plugin>
  </gazebo>

  <gazebo>
    <plugin name="drone_internal_gps_sim" filename="libhector_gazebo_ros_gps.so">
      <updateRate>4.0</updateRate>
      <bodyName>base_link</bodyName>
      <frameId>base_link</frameId>
      <topicName>GPS/fix</topicName>
      <velocityTopicName>GPS/fix_velocity</velocityTopicName>
      <referenceLatitude>49.860246</referenceLatitude>
      <referenceLongitude>8.687077</referenceLongitude>
      <drift>0.0 0.0 0.0</drift>
      <gaussianNoise>0.01 0.01 0.01</gaussianNoise>
      <velocityDrift>0 0 0</velocityDrift>
      <velocityGaussianNoise>0.01 0.01 0.01</velocityGaussianNoise>
    </plugin>
  </gazebo>

  <gazebo reference="base_link">
    <sensor type="camera" name="camera1">
      <update_rate>30.0</update_rate>
      <camera name="head">
        <vertical_fov>3.1415926</vertical_fov>
        <image>
          <width>800</width>
          <height>800</height>
          <format>R8G8B8</format>
        </image>
        <clip>
          <near>0.02</near>
          <far>300</far>
        </clip>
        <noise>
          <type>gaussian</type>  -->
          <!-- Noise is sampled independently per pixel on each frame.
               That pixel's noise value is added to each of its color
               channels, which at that point lie in the range [0,1]. -->
          <mean>0.0</mean>
          <stddev>0.007</stddev>
        </noise>
      </camera>
      <plugin name="camera_controller" filename="libgazebo_ros_camera.so">
        <alwaysOn>true</alwaysOn>
        <updateRate>0.0</updateRate>
        <cameraName>camera1</cameraName>
        <imageTopicName>image_raw</imageTopicName>
        <cameraInfoTopicName>camera_info</cameraInfoTopicName>
        <frameName>base_link</frameName>
        <hackBaseline>0.07</hackBaseline>
        <distortionK1>0.0</distortionK1>
        <distortionK2>0.0</distortionK2>
        <distortionK3>0.0</distortionK3>
        <distortionT1>0.0</distortionT1>
        <distortionT2>0.0</distortionT2>
      </plugin>
    </sensor>
  </gazebo>


  <link
    name="base_link">
    <inertial>
      <origin
        xyz="3.9269E-15 8.4015E-15 -0.018301"
        rpy="0 0 0" />
      <mass
        value="4.5104" />
      <inertia
        ixx="0.2003"
        ixy="0.00024017"
        ixz="-8.2287E-16"
        iyy="0.074429"
        iyz="-1.9116E-14"
        izz="0.20479" />
    </inertial>
    <visual>
      <origin
        xyz="0 0 0"
        rpy="0 0 0" />
      <geometry>
        <mesh
          filename="package://flypulator_description/meshes/base_link.STL" />
      </geometry>
      <material
        name="">
        <color
          rgba="0.75294 0.75294 0.75294 1" />
      </material>
    </visual>
    <collision>
      <origin
        xyz="0 0 0"
        rpy="0 0 0" />
      <geometry>
        <mesh
          filename="package://flypulator_description/meshes/base_link.STL" />
      </geometry>
    </collision>
  </link>
  <link
    name="arm_link_1">
    <inertial>
      <origin
        xyz="7.5838E-05 0.35929 0.00028889"
        rpy="0 0 0" />
      <mass
        value="0.11307" />
      <inertia
        ixx="0.0035834"
        ixy="-1.7536E-06"
        ixz="3.334E-06"
        iyy="2.9806E-05"
        iyz="-6.7287E-06"
        izz="0.0035963" />
    </inertial>
    <visual>
      <origin
        xyz="0 0 0"
        rpy="0 0 0" />
      <geometry>
        <mesh
          filename="package://flypulator_description/meshes/arm_link_1.STL" />
      </geometry>
      <material
        name="">
        <color
          rgba="1 1 1 1" />
      </material>
    </visual>
    <collision>
      <origin
        xyz="0 0 0"
        rpy="0 0 0" />
      <geometry>
        <mesh
          filename="package://flypulator_description/meshes/arm_link_1.STL" />
      </geometry>
    </collision>
  </link>
  <joint
    name="arm_joint_1"
    type="fixed">
    <origin
      xyz="0.0379263277638919 -0.0218967755438572 0.03"
      rpy="6.5556015652822E-16 -1.01435265127275E-15 -2.09439510239319" />
    <parent
      link="base_link" />
    <child
      link="arm_link_1" />
    <axis
      xyz="0 0 0" />
  </joint>
  <link
    name="motor_link_1">
    <inertial>
      <origin
        xyz="2.0629E-07 -3.6291E-08 0.019536"
        rpy="0 0 0" />
      <mass
        value="0.098041" />
      <inertia
        ixx="3.2619E-05"
        ixy="-3.493E-10"
        ixz="3.4958E-10"
        iyy="3.2621E-05"
        iyz="-6.3762E-11"
        izz="4.3659E-05" />
    </inertial>
    <visual>
      <origin
        xyz="0 0 0"
        rpy="0 0 0" />
      <geometry>
        <mesh
          filename="package://flypulator_description/meshes/motor_link_1.STL" />
      </geometry>
      <material
        name="">
        <color
          rgba="0.2 0.2 0.2 1" />
      </material>
    </visual>
    <collision>
      <origin
        xyz="0 0 0"
        rpy="0 0 0" />
      <geometry>
        <mesh
          filename="package://flypulator_description/meshes/motor_link_1.STL" />
      </geometry>
    </collision>
  </link>
  <joint
    name="motor_joint_1"
    type="fixed">
    <origin
      xyz="0.0011025 0.5623 0.0048775"
      rpy="-0.23736 -0.00041702 -1.5725" />
    <parent
      link="arm_link_1" />
    <child
      link="motor_link_1" />
    <axis
      xyz="0 0 0" />
  </joint>
  <link
    name="blade_link_1">
    <inertial>
      <origin
        xyz="3.7145E-06 1.0619E-06 -0.0016268"
        rpy="0 0 0" />
      <mass
        value="0.062744" />
      <inertia
        ixx="7.9927E-06"
        ixy="2.4595E-05"
        ixz="5.8974E-10"
        iyy="0.0014004"
        iyz="1.7645E-10"
        izz="0.0014072" />
    </inertial>
    <visual>
      <origin
        xyz="0 0 0"
        rpy="0 0 0" />
      <geometry>
        <mesh
          filename="package://flypulator_description/meshes/blade_link_1.STL" />
      </geometry>
      <material
        name="">
        <color
          rgba="0 0 0 1" />
      </material>
    </visual>
    <collision>
      <origin
        xyz="0 0 0"
        rpy="0 0 0" />
      <geometry>
        <mesh
          filename="package://flypulator_description/meshes/blade_link_1.STL" />
      </geometry>
    </collision>
  </link>
  <joint
    name="blade_joint_1"
    type="continuous">
    <origin
      xyz="0 0 0.046"
      rpy="6.1162E-18 -8.1315E-20 0" />
    <parent
      link="motor_link_1" />
    <child
      link="blade_link_1" />
    <axis
      xyz="0 0 1" />
    <limit
      effort="0"
      velocity="630" />
  </joint>
  <link
    name="arm_link_2">
    <inertial>
      <origin
        xyz="-6.45987155706608E-05 0.359297517735395 0.000291609283292308"
        rpy="0 0 0" />
      <mass
        value="0.113071616632983" />
      <inertia
        ixx="0.00358337872206462"
        ixy="1.51596305369758E-06"
        ixz="-3.3319900957408E-06"
        iyy="2.98059014866106E-05"
        iyz="-6.78615560568246E-06"
        izz="0.00359635047022107" />
    </inertial>
    <visual>
      <origin
        xyz="0 0 0"
        rpy="0 0 0" />
      <geometry>
        <mesh
          filename="package://flypulator_description/meshes/arm_link_2.STL" />
      </geometry>
      <material
        name="">
        <color
          rgba="1 1 1 1" />
      </material>
    </visual>
    <collision>
      <origin
        xyz="0 0 0"
        rpy="0 0 0" />
      <geometry>
        <mesh
          filename="package://flypulator_description/meshes/arm_link_2.STL" />
      </geometry>
    </collision>
  </link>
  <joint
    name="arm_joint_2"
    type="fixed">
    <origin
      xyz="0.0368267925361948 0.0212619585841613 0.0300000000000008"
      rpy="8.02409225127727E-16 -8.45899975464507E-16 -1.0471975511966" />
    <parent
      link="base_link" />
    <child
      link="arm_link_2" />
    <axis
      xyz="0 0 0" />
  </joint>
  <link
    name="motor_link_2">
    <inertial>
      <origin
        xyz="1.27673377314785E-07 1.57053931859608E-07 0.0195362446087649"
        rpy="0 0 0" />
      <mass
        value="0.0980407364233949" />
      <inertia
        ixx="3.26207140793099E-05"
        ixy="-6.6552393914887E-10"
        ixz="2.19396423829522E-10"
        iyy="3.26190970819821E-05"
        iyz="2.69899167424102E-10"
        izz="4.36594955144742E-05" />
    </inertial>
    <visual>
      <origin
        xyz="0 0 0"
        rpy="0 0 0" />
      <geometry>
        <mesh
          filename="package://flypulator_description/meshes/motor_link_2.STL" />
      </geometry>
      <material
        name="">
        <color
          rgba="0.2 0.2 0.2 1" />
      </material>
    </visual>
    <collision>
      <origin
        xyz="0 0 0"
        rpy="0 0 0" />
      <geometry>
        <mesh
          filename="package://flypulator_description/meshes/motor_link_2.STL" />
      </geometry>
    </collision>
  </link>
  <joint
    name="motor_joint_2"
    type="fixed">
    <origin
      xyz="-0.00124895892184227 0.562306513541 0.00484208436052164"
      rpy="0.237364418851718 0.000417019559747398 -1.57252008000707" />
    <parent
      link="arm_link_2" />
    <child
      link="motor_link_2" />
    <axis
      xyz="0 0 0" />
  </joint>
  <link
    name="blade_link_2">
    <inertial>
      <origin
        xyz="-1.4065876085545E-05 -2.55237663435159E-06 -0.00162646027121978"
        rpy="0 0 0" />
      <mass
        value="0.0627428767604964" />
      <inertia
        ixx="8.36866833291662E-06"
        ixy="3.36333705844784E-05"
        ixz="-2.0544463406869E-09"
        iyy="0.001400131781522"
        iyz="-4.4118071653896E-10"
        izz="0.00140738407622868" />
    </inertial>
    <visual>
      <origin
        xyz="0 0 0"
        rpy="0 0 0" />
      <geometry>
        <mesh
          filename="package://flypulator_description/meshes/blade_link_2.STL" />
      </geometry>
      <material
        name="">
        <color
          rgba="0 0 0 1" />
      </material>
    </visual>
    <collision>
      <origin
        xyz="0 0 0"
        rpy="0 0 0" />
      <geometry>
        <mesh
          filename="package://flypulator_description/meshes/blade_link_2.STL" />
      </geometry>
    </collision>
  </link>
  <joint
    name="blade_joint_2"
    type="continuous">
    <origin
      xyz="0 0 0.046"
      rpy="8.0491E-16 0 -5.5511E-17" />
    <parent
      link="motor_link_2" />
    <child
      link="blade_link_2" />
    <axis
      xyz="0 0 1" />
    <limit
      effort="0"
      velocity="630" />
  </joint>
  <link
    name="arm_link_3">
    <inertial>
      <origin
        xyz="7.5838155291795E-05 0.35929751798952 0.000288890203180497"
        rpy="0 0 0" />
      <mass
        value="0.113071616827671" />
      <inertia
        ixx="0.00358337978027546"
        ixy="-1.7536051706911E-06"
        ixz="3.33404096432986E-06"
        iyy="2.98059015235748E-05"
        iyz="-6.72866419460223E-06"
        izz="0.00359634942044135" />
    </inertial>
    <visual>
      <origin
        xyz="0 0 0"
        rpy="0 0 0" />
      <geometry>
        <mesh
          filename="package://flypulator_description/meshes/arm_link_3.STL" />
      </geometry>
      <material
        name="">
        <color
          rgba="1 1 1 1" />
      </material>
    </visual>
    <collision>
      <origin
        xyz="0 0 0"
        rpy="0 0 0" />
      <geometry>
        <mesh
          filename="package://flypulator_description/meshes/arm_link_3.STL" />
      </geometry>
    </collision>
  </link>
  <joint
    name="arm_joint_3"
    type="fixed">
    <origin
      xyz="0 0.0437852352480928 0.0300000000000009"
      rpy="8.9161997561106E-17 4.34108246398995E-14 -1.11022302462516E-16" />
    <parent
      link="base_link" />
    <child
      link="arm_link_3" />
    <axis
      xyz="0 0 0" />
  </joint>
  <link
    name="motor_link_3">
    <inertial>
      <origin
        xyz="-1.85010233688665E-07 -8.65308782405094E-08 0.0195362442133871"
        rpy="0 0 0" />
      <mass
        value="0.0980407398276978" />
      <inertia
        ixx="3.26198912586558E-05"
        ixy="-1.04178195709081E-09"
        ixz="-3.16009189124849E-10"
        iyy="3.26199272198111E-05"
        iyz="-1.49217697437535E-10"
        izz="4.36595022787714E-05" />
    </inertial>
    <visual>
      <origin
        xyz="0 0 0"
        rpy="0 0 0" />
      <geometry>
        <mesh
          filename="package://flypulator_description/meshes/motor_link_3.STL" />
      </geometry>
      <material
        name="">
        <color
          rgba="0.2 0.2 0.2 1" />
      </material>
    </visual>
    <collision>
      <origin
        xyz="0 0 0"
        rpy="0 0 0" />
      <geometry>
        <mesh
          filename="package://flypulator_description/meshes/motor_link_3.STL" />
      </geometry>
    </collision>
  </link>
  <joint
    name="motor_joint_3"
    type="fixed">
    <origin
      xyz="0.00110246220918394 0.562306513541 0.00487752564526059"
      rpy="-0.237364418851689 -0.000417019559749972 -1.57252008000707" />
    <parent
      link="arm_link_3" />
    <child
      link="motor_link_3" />
    <axis
      xyz="0 0 0" />
  </joint>
  <link
    name="blade_link_3">
    <inertial>
      <origin
        xyz="2.39721083415967E-05 3.43436363869909E-06 -0.00162644083949853"
        rpy="0 0 0" />
      <mass
        value="0.0627473719638348" />
      <inertia
        ixx="7.61162990923721E-06"
        ixy="-8.73671881165227E-06"
        ixz="1.64909561297701E-09"
        iyy="0.00140104844094952"
        iyz="4.1878215671187E-10"
        izz="0.00140754364741932" />
    </inertial>
    <visual>
      <origin
        xyz="0 0 0"
        rpy="0 0 0" />
      <geometry>
        <mesh
          filename="package://flypulator_description/meshes/blade_link_3.STL" />
      </geometry>
      <material
        name="">
        <color
          rgba="0 0 0 1" />
      </material>
    </visual>
    <collision>
      <origin
        xyz="0 0 0"
        rpy="0 0 0" />
      <geometry>
        <mesh
          filename="package://flypulator_description/meshes/blade_link_3.STL" />
      </geometry>
    </collision>
  </link>
  <joint
    name="blade_joint_3"
    type="continuous">
    <origin
      xyz="0 0 0.046"
      rpy="-4.1154E-08 2.7756E-17 -5.5511E-17" />
    <parent
      link="motor_link_3" />
    <child
      link="blade_link_3" />
    <axis
      xyz="0 0 1" />
    <limit
      effort="0"
      velocity="630" />
  </joint>
  <link
    name="arm_link_4">
    <inertial>
      <origin
        xyz="0.000309848428748983 0.359287787025405 0.00048199542235914"
        rpy="0 0 0" />
      <mass
        value="0.113071614536243" />
      <inertia
        ixx="0.00358337799003561"
        ixy="-2.18577034743147E-06"
        ixz="-3.34022311248574E-06"
        iyy="2.9814790798697E-05"
        iyz="-8.67257978822727E-06"
        izz="0.0035963422444839" />
    </inertial>
    <visual>
      <origin
        xyz="0 0 0"
        rpy="0 0 0" />
      <geometry>
        <mesh
          filename="package://flypulator_description/meshes/arm_link_4.STL" />
      </geometry>
      <material
        name="">
        <color
          rgba="1 1 1 1" />
      </material>
    </visual>
    <collision>
      <origin
        xyz="0 0 0"
        rpy="0 0 0" />
      <geometry>
        <mesh
          filename="package://flypulator_description/meshes/arm_link_4.STL" />
      </geometry>
    </collision>
  </link>
  <joint
    name="arm_joint_4"
    type="fixed">
    <origin
      xyz="-0.0379272628526742 0.0218973154176168 0.03"
      rpy="-0.000529898657228908 2.74334852536435E-07 1.04823974425529" />
    <parent
      link="base_link" />
    <child
      link="arm_link_4" />
    <axis
      xyz="0 0 0" />
  </joint>
  <link
    name="motor_link_4">
    <inertial>
      <origin
        xyz="-2.06294589188971E-07 3.62905190291057E-08 0.0195362496329407"
        rpy="0 0 0" />
      <mass
        value="0.0980406960173388" />
      <inertia
        ixx="3.26188033140448E-05"
        ixy="-3.49302598897242E-10"
        ixz="-3.49575062028036E-10"
        iyy="3.26209244263571E-05"
        iyz="6.37620073400378E-11"
        izz="4.36594174532518E-05" />
    </inertial>
    <visual>
      <origin
        xyz="0 0 0"
        rpy="0 0 0" />
      <geometry>
        <mesh
          filename="package://flypulator_description/meshes/motor_link_4.STL" />
      </geometry>
      <material
        name="">
        <color
          rgba="0.2 0.2 0.2 1" />
      </material>
    </visual>
    <collision>
      <origin
        xyz="0 0 0"
        rpy="0 0 0" />
      <geometry>
        <mesh
          filename="package://flypulator_description/meshes/motor_link_4.STL" />
      </geometry>
    </collision>
  </link>
  <joint
    name="motor_joint_4"
    type="fixed">
    <origin
      xyz="-0.000662937524737199 0.56229546947751 0.00514004450059716"
      rpy="0.237363227515671 0.000946916948792575 -1.5735622739509" />
    <parent
      link="arm_link_4" />
    <child
      link="motor_link_4" />
    <axis
      xyz="0 0 0" />
  </joint>
  <link
    name="blade_link_4">
    <inertial>
      <origin
        xyz="-5.8684492045824E-06 -1.12567952349242E-06 -0.00162678065694306"
        rpy="0 0 0" />
      <mass
        value="0.062744669954973" />
      <inertia
        ixx="1.00684183373283E-05"
        ixy="5.90869014021767E-05"
        ixz="-1.05706811451692E-09"
        iyy="0.00139834222563913"
        iyz="-1.77328404330078E-10"
        izz="0.00140729381779738" />
    </inertial>
    <visual>
      <origin
        xyz="0 0 0"
        rpy="0 0 0" />
      <geometry>
        <mesh
          filename="package://flypulator_description/meshes/blade_link_4.STL" />
      </geometry>
      <material
        name="">
        <color
          rgba="0 0 0 1" />
      </material>
    </visual>
    <collision>
      <origin
        xyz="0 0 0"
        rpy="0 0 0" />
      <geometry>
        <mesh
          filename="package://flypulator_description/meshes/blade_link_4.STL" />
      </geometry>
    </collision>
  </link>
  <joint
    name="blade_joint_4"
    type="continuous">
    <origin
      xyz="0 0 0.046"
      rpy="-8.888E-17 -6.7763E-20 -4.3368E-19" />
    <parent
      link="motor_link_4" />
    <child
      link="blade_link_4" />
    <axis
      xyz="0 0 1" />
    <limit
      effort="0"
      velocity="630" />
  </joint>
  <link
    name="arm_link_5">
    <inertial>
      <origin
        xyz="7.58387640751E-05 0.359297512493941 0.000288889903746748"
        rpy="0 0 0" />
      <mass
        value="0.113071612209128" />
      <inertia
        ixx="0.00358337969566119"
        ixy="-1.75361404286493E-06"
        ixz="3.33404115374709E-06"
        iyy="2.98059009237571E-05"
        iyz="-6.72865991392346E-06"
        izz="0.00359634933545393" />
    </inertial>
    <visual>
      <origin
        xyz="0 0 0"
        rpy="0 0 0" />
      <geometry>
        <mesh
          filename="package://flypulator_description/meshes/arm_link_5.STL" />
      </geometry>
      <material
        name="">
        <color
          rgba="1 1 1 1" />
      </material>
    </visual>
    <collision>
      <origin
        xyz="0 0 0"
        rpy="0 0 0" />
      <geometry>
        <mesh
          filename="package://flypulator_description/meshes/arm_link_5.STL" />
      </geometry>
    </collision>
  </link>
  <joint
    name="arm_joint_5"
    type="fixed">
    <origin
      xyz="-0.0368267925361943 -0.0212619585841622 0.0300000000000001"
      rpy="2.38424860458359E-16 -5.05424148413291E-16 2.09439510239319" />
    <parent
      link="base_link" />
    <child
      link="arm_link_5" />
    <axis
      xyz="0 0 0" />
  </joint>
  <link
    name="motor_link_5">
    <inertial>
      <origin
        xyz="-6.66302263363505E-08 1.97997260587002E-07 0.0195362472105891"
        rpy="0 0 0" />
      <mass
        value="0.0980407161578018" />
      <inertia
        ixx="3.26201560138298E-05"
        ixy="1.04792842556447E-09"
        ixz="-1.11000640600106E-10"
        iyy="3.2619613350915E-05"
        iyz="3.36992577574994E-10"
        izz="4.36594566063806E-05" />
    </inertial>
    <visual>
      <origin
        xyz="0 0 0"
        rpy="0 0 0" />
      <geometry>
        <mesh
          filename="package://flypulator_description/meshes/motor_link_5.STL" />
      </geometry>
      <material
        name="">
        <color
          rgba="0.2 0.2 0.2 1" />
      </material>
    </visual>
    <collision>
      <origin
        xyz="0 0 0"
        rpy="0 0 0" />
      <geometry>
        <mesh
          filename="package://flypulator_description/meshes/motor_link_5.STL" />
      </geometry>
    </collision>
  </link>
  <joint
    name="motor_joint_5"
    type="fixed">
    <origin
      xyz="0.001102462209182 0.562306513541 0.00487752564526311"
      rpy="-0.237364418851719 -0.000417019559769994 -1.57252008000713" />
    <parent
      link="arm_link_5" />
    <child
      link="motor_link_5" />
    <axis
      xyz="0 0 0" />
  </joint>
  <link
    name="blade_link_5">
    <inertial>
      <origin
        xyz="1.4066E-05 2.5524E-06 -0.0016265"
        rpy="0 0 0" />
      <mass
        value="0.062743" />
      <inertia
        ixx="8.3687E-06"
        ixy="3.3633E-05"
        ixz="2.0545E-09"
        iyy="0.0014001"
        iyz="4.4118E-10"
        izz="0.0014074" />
    </inertial>
    <visual>
      <origin
        xyz="0 0 0"
        rpy="0 0 0" />
      <geometry>
        <mesh
          filename="package://flypulator_description/meshes/blade_link_5.STL" />
      </geometry>
      <material
        name="">
        <color
          rgba="0 0 0 1" />
      </material>
    </visual>
    <collision>
      <origin
        xyz="0 0 0"
        rpy="0 0 0" />
      <geometry>
        <mesh
          filename="package://flypulator_description/meshes/blade_link_5.STL" />
      </geometry>
    </collision>
  </link>
  <joint
    name="blade_joint_5"
    type="continuous">
    <origin
      xyz="0 0 0.046"
      rpy="-7.7716E-16 0 0" />
    <parent
      link="motor_link_5" />
    <child
      link="blade_link_5" />
    <axis
      xyz="0 0 1" />
    <limit
      effort="0"
      velocity="630" />
  </joint>
  <link
    name="arm_link_6">
    <inertial>
      <origin
        xyz="-6.4599E-05 0.3593 0.00029161"
        rpy="0 0 0" />
      <mass
        value="0.11307" />
      <inertia
        ixx="0.0035834"
        ixy="1.516E-06"
        ixz="-3.332E-06"
        iyy="2.9806E-05"
        iyz="-6.7862E-06"
        izz="0.0035964" />
    </inertial>
    <visual>
      <origin
        xyz="0 0 0"
        rpy="0 0 0" />
      <geometry>
        <mesh
          filename="package://flypulator_description/meshes/arm_link_6.STL" />
      </geometry>
      <material
        name="">
        <color
          rgba="1 1 1 1" />
      </material>
    </visual>
    <collision>
      <origin
        xyz="0 0 0"
        rpy="0 0 0" />
      <geometry>
        <mesh
          filename="package://flypulator_description/meshes/arm_link_6.STL" />
      </geometry>
    </collision>
  </link>
  <joint
    name="arm_joint_6"
    type="fixed">
    <origin
      xyz="0 -0.0437852352480966 0.0300000000000001"
      rpy="9.38614440953606E-16 1.69378355161205E-16 -3.14159265358979" />
    <parent
      link="base_link" />
    <child
      link="arm_link_6" />
    <axis
      xyz="0 0 0" />
  </joint>
  <link
    name="motor_link_6">
    <inertial>
      <origin
        xyz="1.4274E-07 1.5405E-07 0.019536"
        rpy="0 0 0" />
      <mass
        value="0.098041" />
      <inertia
        ixx="3.2621E-05"
        ixy="-7.9538E-10"
        ixz="2.4353E-10"
        iyy="3.2619E-05"
        iyz="2.5954E-10"
        izz="4.3659E-05" />
    </inertial>
    <visual>
      <origin
        xyz="0 0 0"
        rpy="0 0 0" />
      <geometry>
        <mesh
          filename="package://flypulator_description/meshes/motor_link_6.STL" />
      </geometry>
      <material
        name="">
        <color
          rgba="0.2 0.2 0.2 1" />
      </material>
    </visual>
    <collision>
      <origin
        xyz="0 0 0"
        rpy="0 0 0" />
      <geometry>
        <mesh
          filename="package://flypulator_description/meshes/motor_link_6.STL" />
      </geometry>
    </collision>
  </link>
  <joint
    name="motor_joint_6"
    type="fixed">
    <origin
      xyz="-0.00124895892184055 0.562306513541 0.00484208436052314"
      rpy="0.237364418851732 0.000417019559751141 -1.57252008000707" />
    <parent
      link="arm_link_6" />
    <child
      link="motor_link_6" />
    <axis
      xyz="0 0 0" />
  </joint>
  <link
    name="blade_link_6">
    <inertial>
      <origin
        xyz="-2.3972E-05 -3.4343E-06 -0.0016264"
        rpy="0 0 0" />
      <mass
        value="0.062747" />
      <inertia
        ixx="7.6116E-06"
        ixy="-8.7367E-06"
        ixz="-1.6495E-09"
        iyy="0.001401"
        iyz="-4.1905E-10"
        izz="0.0014075" />
    </inertial>
    <visual>
      <origin
        xyz="0 0 0"
        rpy="0 0 0" />
      <geometry>
        <mesh
          filename="package://flypulator_description/meshes/blade_link_6.STL" />
      </geometry>
      <material
        name="">
        <color
          rgba="0 0 0 1" />
      </material>
    </visual>
    <collision>
      <origin
        xyz="0 0 0"
        rpy="0 0 0" />
      <geometry>
        <mesh
          filename="package://flypulator_description/meshes/blade_link_6.STL" />
      </geometry>
    </collision>
  </link>
  <joint
    name="blade_joint_6"
    type="continuous">
    <origin
      xyz="0 0 0.046"
      rpy="-1.1102E-16 1.3878E-17 -5.5511E-17" />
    <parent
      link="motor_link_6" />
    <child
      link="blade_link_6" />
    <axis
      xyz="0 0 1" />
    <limit
      effort="0"
      velocity="630" />
  </joint>
</robot>