<?xml version="1.0"?>
<robot
  name="Hexacopter">
  <link
    name="base_link">
    <inertial>
      <origin
        xyz="9.2213E-15 7.9967E-16 -0.018301"
        rpy="0 0 0" />
      <mass
        value="4.5104" />
      <inertia
        ixx="0.10606"
        ixy="-0.054598"
        ixz="-1.7113E-14"
        iyy="0.16867"
        iyz="-8.9166E-15"
        izz="0.20479" />
    </inertial>
    <visual>
      <origin
        xyz="0 0 0"
        rpy="0 0 0" />
      <geometry>
        <mesh
          filename="package://flypulator_description/meshes/base_link.STL" />
      </geometry>
      <material
        name="">
        <color
          rgba="0.75294 0.75294 0.75294 1" />
      </material>
    </visual>
    <collision>
      <origin
        xyz="0 0 0"
        rpy="0 0 0" />
      <geometry>
        <mesh
          filename="package://flypulator_description/meshes/base_link.STL" />
      </geometry>
    </collision>
  </link>
  <link
    name="arm_link_1">
    <inertial>
      <origin
        xyz="0.000103897093480426 0.399726905874718 0.000395773095830526"
        rpy="0 0 0" />
      <mass
        value="0.0825353339299331" />
      <inertia
        ixx="0.0024452540773567"
        ixy="-1.40684929852721E-06"
        ixz="3.33495757682309E-06"
        iyy="2.53973107200894E-05"
        iyz="-5.40775270776347E-06"
        izz="0.00245822696803879" />
    </inertial>
    <visual>
      <origin
        xyz="0 0 0"
        rpy="0 0 0" />
      <geometry>
        <mesh
          filename="package://flypulator_description/meshes/arm_link_1.STL" />
      </geometry>
      <material
        name="">
        <color
          rgba="0.501960784313725 0.501960784313725 0.501960784313725 1" />
      </material>
    </visual>
    <collision>
      <origin
        xyz="0 0 0"
        rpy="0 0 0" />
      <geometry>
        <mesh
          filename="package://flypulator_description/meshes/arm_link_1.STL" />
      </geometry>
    </collision>
  </link>
  <joint
    name="arm_joint_1"
    type="fixed">
    <origin
      xyz="-1.7301E-05 -0.043794 0.03"
      rpy="1.3062E-16 2.419E-20 3.1412" />
    <parent
      link="base_link" />
    <child
      link="arm_link_1" />
    <axis
      xyz="0 0 0" />
  </joint>
  <link
    name="motor_link_1">
    <inertial>
      <origin
        xyz="-3.62905190499224E-08 0.0195362496329407 2.06294589411016E-07"
        rpy="0 0 0" />
      <mass
        value="0.0980406960173389" />
      <inertia
        ixx="3.26209244263572E-05"
        ixy="-6.37620073044127E-11"
        ixz="-3.49302598878336E-10"
        iyy="4.36594174532518E-05"
        iyz="3.49575062055282E-10"
        izz="3.26188033140448E-05" />
    </inertial>
    <visual>
      <origin
        xyz="0 0 0"
        rpy="0 0 0" />
      <geometry>
        <mesh
          filename="package://flypulator_description/meshes/motor_link_1.STL" />
      </geometry>
      <material
        name="">
        <color
          rgba="0.2 0.2 0.2 1" />
      </material>
    </visual>
    <collision>
      <origin
        xyz="0 0 0"
        rpy="0 0 0" />
      <geometry>
        <mesh
          filename="package://flypulator_description/meshes/motor_link_1.STL" />
      </geometry>
    </collision>
  </link>
  <joint
    name="motor_joint_1"
    type="fixed">
    <origin
      xyz="0.0011025 0.5623 0.0048775"
      rpy="1.5704 0.23736 -0.0018246" />
    <parent
      link="arm_link_1" />
    <child
      link="motor_link_1" />
    <axis
      xyz="0 0 0" />
  </joint>
  <link
    name="blade_link_1">
    <inertial>
      <origin
        xyz="-1.0538E-06 -0.0016268 -3.7168E-06"
        rpy="0 0 0" />
      <mass
        value="0.062744" />
      <inertia
        ixx="0.0014003"
        ixy="-1.7517E-10"
        ixz="2.763E-05"
        iyy="0.0014072"
        iyz="-5.9013E-10"
        izz="8.1065E-06" />
    </inertial>
    <visual>
      <origin
        xyz="0 0 0"
        rpy="0 0 0" />
      <geometry>
        <mesh
          filename="package://flypulator_description/meshes/blade_link_1.STL" />
      </geometry>
      <material
        name="">
        <color
          rgba="0 0 0 1" />
      </material>
    </visual>
    <collision>
      <origin
        xyz="0 0 0"
        rpy="0 0 0" />
      <geometry>
        <mesh
          filename="package://flypulator_description/meshes/blade_link_1.STL" />
      </geometry>
    </collision>
  </link>
  <joint
    name="blade_joint_1"
    type="continuous">
    <origin
      xyz="0 0.046 0"
      rpy="3.1416 -0.0021799 -3.1416" />
    <parent
      link="motor_link_1" />
    <child
      link="blade_link_1" />
    <axis
      xyz="0 1 0" />
    <limit
      effort="0"
      velocity="630" />
  </joint>
  <link
    name="arm_link_2">
    <inertial>
      <origin
        xyz="-8.8499E-05 0.39974 0.0003995"
        rpy="0 0 0" />
      <mass
        value="0.082535" />
      <inertia
        ixx="0.0024453"
        ixy="1.2206E-06"
        ixz="-3.3328E-06"
        iyy="2.5397E-05"
        iyz="-5.4528E-06"
        izz="0.0024582" />
    </inertial>
    <visual>
      <origin
        xyz="0 0 0"
        rpy="0 0 0" />
      <geometry>
        <mesh
          filename="package://flypulator_description/meshes/arm_link_2.STL" />
      </geometry>
      <material
        name="">
        <color
          rgba="0.50196 0.50196 0.50196 1" />
      </material>
    </visual>
    <collision>
      <origin
        xyz="0 0 0"
        rpy="0 0 0" />
      <geometry>
        <mesh
          filename="package://flypulator_description/meshes/arm_link_2.STL" />
      </geometry>
    </collision>
  </link>
  <joint
    name="arm_joint_2"
    type="fixed">
    <origin
      xyz="0.036818 -0.021277 0.03"
      rpy="1.4184E-15 1.159E-16 -2.0948" />
    <parent
      link="base_link" />
    <child
      link="arm_link_2" />
    <axis
      xyz="0 0 0" />
  </joint>
  <link
    name="motor_link_2">
    <inertial>
      <origin
        xyz="1.57053931859608E-07 0.0195362446087649 1.27673377314785E-07"
        rpy="0 0 0" />
      <mass
        value="0.0980407364233949" />
      <inertia
        ixx="3.26190970819821E-05"
        ixy="2.69899167425796E-10"
        ixz="-6.65523939146329E-10"
        iyy="4.36594955144742E-05"
        iyz="2.19396423829099E-10"
        izz="3.26207140793099E-05" />
    </inertial>
    <visual>
      <origin
        xyz="0 0 0"
        rpy="0 0 0" />
      <geometry>
        <mesh
          filename="package://flypulator_description/meshes/motor_link_2.STL" />
      </geometry>
      <material
        name="">
        <color
          rgba="0.2 0.2 0.2 1" />
      </material>
    </visual>
    <collision>
      <origin
        xyz="0 0 0"
        rpy="0 0 0" />
      <geometry>
        <mesh
          filename="package://flypulator_description/meshes/motor_link_2.STL" />
      </geometry>
    </collision>
  </link>
  <joint
    name="motor_joint_2"
    type="fixed">
    <origin
      xyz="-0.001249 0.56231 0.0048421"
      rpy="1.5712 -0.23736 -0.0018246" />
    <parent
      link="arm_link_2" />
    <child
      link="motor_link_2" />
    <axis
      xyz="0 0 0" />
  </joint>
  <link
    name="blade_link_2">
    <inertial>
      <origin
        xyz="1.35053988399303E-05 -0.00162646027128877 4.68680956727807E-06"
        rpy="0 0 0" />
      <mass
        value="0.0627428767635787" />
      <inertia
        ixx="0.000373034206122547"
        ixy="2.00616409657325E-09"
        ixz="-0.000612926009735943"
        iyy="0.00140738407647423"
        iyz="6.24976862647589E-10"
        izz="0.00103546624397724" />
    </inertial>
    <visual>
      <origin
        xyz="0 0 0"
        rpy="0 0 0" />
      <geometry>
        <mesh
          filename="package://flypulator_description/meshes/blade_link_2.STL" />
      </geometry>
      <material
        name="">
        <color
          rgba="0 0 0 1" />
      </material>
    </visual>
    <collision>
      <origin
        xyz="0 0 0"
        rpy="0 0 0" />
      <geometry>
        <mesh
          filename="package://flypulator_description/meshes/blade_link_2.STL" />
      </geometry>
    </collision>
  </link>
  <joint
    name="blade_joint_2"
    type="continuous">
    <origin
      xyz="0 0.046 0"
      rpy="3.1416 1.0573 3.1416" />
    <parent
      link="motor_link_2" />
    <child
      link="blade_link_2" />
    <axis
      xyz="0 1 0" />
    <limit
      effort="0"
      velocity="630" />
  </joint>
  <link
    name="arm_link_3">
    <inertial>
      <origin
        xyz="0.0001039 0.39974 0.00039577"
        rpy="0 0 0" />
      <mass
        value="0.082535" />
      <inertia
        ixx="0.0024453"
        ixy="-1.4068E-06"
        ixz="3.335E-06"
        iyy="2.5397E-05"
        iyz="-5.4078E-06"
        izz="0.0024582" />
    </inertial>
    <visual>
      <origin
        xyz="0 0 0"
        rpy="0 0 0" />
      <geometry>
        <mesh
          filename="package://flypulator_description/meshes/arm_link_3.STL" />
      </geometry>
      <material
        name="">
        <color
          rgba="0.50196 0.50196 0.50196 1" />
      </material>
    </visual>
    <collision>
      <origin
        xyz="0 0 0"
        rpy="0 0 0" />
      <geometry>
        <mesh
          filename="package://flypulator_description/meshes/arm_link_3.STL" />
      </geometry>
    </collision>
  </link>
  <joint
    name="arm_joint_3"
    type="fixed">
    <origin
      xyz="0.037928 0.021878 0.03"
      rpy="1.2301E-15 4.3358E-14 -1.0476" />
    <parent
      link="base_link" />
    <child
      link="arm_link_3" />
    <axis
      xyz="0 0 0" />
  </joint>
  <link
    name="motor_link_3">
    <inertial>
      <origin
        xyz="0.00460748433050506 0.018985150147332 -1.85010233688665E-07"
        rpy="0 0 0" />
      <mass
        value="0.0980407398276978" />
      <inertia
        ixx="3.32339230384055E-05"
        ixy="2.53007155675009E-06"
        ixz="-1.08692332793556E-09"
        iyy="4.30455064601769E-05"
        iyz="-6.13932644806273E-11"
        izz="3.26198912586558E-05" />
    </inertial>
    <visual>
      <origin
        xyz="0 0 0"
        rpy="0 0 0" />
      <geometry>
        <mesh
          filename="package://flypulator_description/meshes/motor_link_3.STL" />
      </geometry>
      <material
        name="">
        <color
          rgba="0.2 0.2 0.2 1" />
      </material>
    </visual>
    <collision>
      <origin
        xyz="0 0 0"
        rpy="0 0 0" />
      <geometry>
        <mesh
          filename="package://flypulator_description/meshes/motor_link_3.STL" />
      </geometry>
    </collision>
  </link>
  <joint
    name="motor_joint_3"
    type="fixed">
    <origin
      xyz="0.0011025 0.56231 0.0048775"
      rpy="1.5704 -0.00072585 -0.0017235" />
    <parent
      link="arm_link_3" />
    <child
      link="motor_link_3" />
    <axis
      xyz="0 0 0" />
  </joint>
  <link
    name="blade_link_3">
    <inertial>
      <origin
        xyz="-3.39184421546679E-06 -0.00162644083950024 -2.39781612950685E-05"
        rpy="0 0 0" />
      <mass
        value="0.0627473719638348" />
      <inertia
        ixx="0.00140107504699655"
        ixy="-4.15857307004821E-10"
        ixz="-6.26543712560556E-06"
        iyy="0.00140754364741932"
        iyz="-1.64993788492494E-09"
        izz="7.58502386220083E-06" />
    </inertial>
    <visual>
      <origin
        xyz="0 0 0"
        rpy="0 0 0" />
      <geometry>
        <mesh
          filename="package://flypulator_description/meshes/blade_link_3.STL" />
      </geometry>
      <material
        name="">
        <color
          rgba="0 0 0 1" />
      </material>
    </visual>
    <collision>
      <origin
        xyz="0 0 0"
        rpy="0 0 0" />
      <geometry>
        <mesh
          filename="package://flypulator_description/meshes/blade_link_3.STL" />
      </geometry>
    </collision>
  </link>
  <joint
    name="blade_joint_3"
    type="continuous">
    <origin
      xyz="0.010849 0.044702 0"
      rpy="-3.1416 -0.0017735 2.9035" />
    <parent
      link="motor_link_3" />
    <child
      link="blade_link_3" />
    <axis
      xyz="0 1 0" />
    <limit
      effort="0"
      velocity="630" />
  </joint>
  <link
    name="arm_link_4">
    <inertial>
      <origin
        xyz="0.00032809 0.39973 0.00061131"
        rpy="0 0 0" />
      <mass
        value="0.082535" />
      <inertia
        ixx="0.0024453"
        ixy="-1.2996E-06"
        ixz="-3.3392E-06"
        iyy="2.5404E-05"
        iyz="-6.7385E-06"
        izz="0.0024582" />
    </inertial>
    <visual>
      <origin
        xyz="0 0 0"
        rpy="0 0 0" />
      <geometry>
        <mesh
          filename="package://flypulator_description/meshes/arm_link_4.STL" />
      </geometry>
      <material
        name="">
        <color
          rgba="0.50196 0.50196 0.50196 1" />
      </material>
    </visual>
    <collision>
      <origin
        xyz="0 0 0"
        rpy="0 0 0" />
      <geometry>
        <mesh
          filename="package://flypulator_description/meshes/arm_link_4.STL" />
      </geometry>
    </collision>
  </link>
  <joint
    name="arm_joint_4"
    type="fixed">
    <origin
      xyz="1.7302E-05 0.043795 0.03"
      rpy="-0.0005299 2.7433E-07 0.00064712" />
    <parent
      link="base_link" />
    <child
      link="arm_link_4" />
    <axis
      xyz="0 0 0" />
  </joint>
  <link
    name="motor_link_4">
    <inertial>
      <origin
        xyz="-0.00459376970105295 0.018988478866291 -2.06294589411016E-07"
        rpy="0 0 0" />
      <mass
        value="0.0980406960173388" />
      <inertia
        ixx="3.32312362217763E-05"
        ixy="-2.52278457550468E-06"
        ixz="-2.57308463602512E-10"
        iyy="4.30491056578326E-05"
        iyz="-4.21909213157402E-10"
        izz="3.26188033140448E-05" />
    </inertial>
    <visual>
      <origin
        xyz="0 0 0"
        rpy="0 0 0" />
      <geometry>
        <mesh
          filename="package://flypulator_description/meshes/motor_link_4.STL" />
      </geometry>
      <material
        name="">
        <color
          rgba="0.2 0.2 0.2 1" />
      </material>
    </visual>
    <collision>
      <origin
        xyz="0 0 0"
        rpy="0 0 0" />
      <geometry>
        <mesh
          filename="package://flypulator_description/meshes/motor_link_4.STL" />
      </geometry>
    </collision>
  </link>
  <joint
    name="motor_joint_4"
    type="fixed">
    <origin
      xyz="-0.00066294 0.5623 0.00514"
      rpy="1.5717 2.0749E-06 -0.0027659" />
    <parent
      link="arm_link_4" />
    <child
      link="motor_link_4" />
    <axis
      xyz="0 0 0" />
  </joint>
  <link
    name="blade_link_4">
    <inertial>
      <origin
        xyz="1.113E-06 -0.0016268 5.8709E-06"
        rpy="0 0 0" />
      <mass
        value="0.062745" />
      <inertia
        ixx="0.0013981"
        ixy="1.7505E-10"
        ixz="6.2082E-05"
        iyy="0.0014073"
        iyz="1.0574E-09"
        izz="1.033E-05" />
    </inertial>
    <visual>
      <origin
        xyz="0 0 0"
        rpy="0 0 0" />
      <geometry>
        <mesh
          filename="package://flypulator_description/meshes/blade_link_4.STL" />
      </geometry>
      <material
        name="">
        <color
          rgba="0 0 0 1" />
      </material>
    </visual>
    <collision>
      <origin
        xyz="0 0 0"
        rpy="0 0 0" />
      <geometry>
        <mesh
          filename="package://flypulator_description/meshes/blade_link_4.STL" />
      </geometry>
    </collision>
  </link>
  <joint
    name="blade_joint_4"
    type="continuous">
    <origin
      xyz="-0.010817 0.04471 0"
      rpy="-3.1416 -0.0021575 -2.9042" />
    <parent
      link="motor_link_4" />
    <child
      link="blade_link_4" />
    <axis
      xyz="0 1 0" />
    <limit
      effort="0"
      velocity="630" />
  </joint>
  <link
    name="arm_link_5">
    <inertial>
      <origin
        xyz="0.000103897460081517 0.399735218919339 0.000395772895412469"
        rpy="0 0 0" />
      <mass
        value="0.0825353316162353" />
      <inertia
        ixx="0.00244525405358723"
        ixy="-1.40685216489359E-06"
        ixz="3.33495769798734E-06"
        iyy="2.53973104796442E-05"
        iyz="-5.40775223864753E-06"
        izz="0.00245822694413006" />
    </inertial>
    <visual>
      <origin
        xyz="0 0 0"
        rpy="0 0 0" />
      <geometry>
        <mesh
          filename="package://flypulator_description/meshes/arm_link_5.STL" />
      </geometry>
      <material
        name="">
        <color
          rgba="0.501960784313725 0.501960784313725 0.501960784313725 1" />
      </material>
    </visual>
    <collision>
      <origin
        xyz="0 0 0"
        rpy="0 0 0" />
      <geometry>
        <mesh
          filename="package://flypulator_description/meshes/arm_link_5.STL" />
      </geometry>
    </collision>
  </link>
  <joint
    name="arm_joint_5"
    type="fixed">
    <origin
      xyz="-0.036818 0.021277 0.03"
      rpy="-3.7758E-16 -1.4672E-15 1.0468" />
    <parent
      link="base_link" />
    <child
      link="arm_link_5" />
    <axis
      xyz="0 0 0" />
  </joint>
  <link
    name="motor_link_5">
    <inertial>
      <origin
        xyz="0.0045803 0.018992 -6.663E-08"
        rpy="0 0 0" />
      <mass
        value="0.098041" />
      <inertia
        ixx="3.3227E-05"
        ixy="2.5164E-06"
        ixz="9.927E-10"
        iyy="4.3053E-05"
        iyz="-3.5359E-10"
        izz="3.262E-05" />
    </inertial>
    <visual>
      <origin
        xyz="0 0 0"
        rpy="0 0 0" />
      <geometry>
        <mesh
          filename="package://flypulator_description/meshes/motor_link_5.STL" />
      </geometry>
      <material
        name="">
        <color
          rgba="0.2 0.2 0.2 1" />
      </material>
    </visual>
    <collision>
      <origin
        xyz="0 0 0"
        rpy="0 0 0" />
      <geometry>
        <mesh
          filename="package://flypulator_description/meshes/motor_link_5.STL" />
      </geometry>
    </collision>
  </link>
  <joint
    name="motor_joint_5"
    type="fixed">
    <origin
      xyz="0.0011025 0.56231 0.0048775"
      rpy="1.5704 0.00071878 -0.0017241" />
    <parent
      link="arm_link_5" />
    <child
      link="motor_link_5" />
    <axis
      xyz="0 0 0" />
  </joint>
  <link
    name="blade_link_5">
    <inertial>
      <origin
        xyz="2.5274E-06 -0.0016265 1.4071E-05"
        rpy="0 0 0" />
      <mass
        value="0.062743" />
      <inertia
        ixx="0.0014"
        ixy="4.3753E-10"
        ixz="3.6101E-05"
        iyy="0.0014074"
        iyz="2.0553E-09"
        izz="8.4923E-06" />
    </inertial>
    <visual>
      <origin
        xyz="0 0 0"
        rpy="0 0 0" />
      <geometry>
        <mesh
          filename="package://flypulator_description/meshes/blade_link_5.STL" />
      </geometry>
      <material
        name="">
        <color
          rgba="0 0 0 1" />
      </material>
    </visual>
    <collision>
      <origin
        xyz="0 0 0"
        rpy="0 0 0" />
      <geometry>
        <mesh
          filename="package://flypulator_description/meshes/blade_link_5.STL" />
      </geometry>
    </collision>
  </link>
  <joint
    name="blade_joint_5"
    type="continuous">
    <origin
      xyz="0.010784 0.044718 0"
      rpy="6.1201E-15 0.0017735 -0.23665" />
    <parent
      link="motor_link_5" />
    <child
      link="blade_link_5" />
    <axis
      xyz="0 1 0" />
    <limit
      effort="0"
      velocity="630" />
  </joint>
  <link
    name="arm_link_6">
    <inertial>
      <origin
        xyz="-8.85E-05 0.39974 0.0003995"
        rpy="0 0 0" />
      <mass
        value="0.082535" />
      <inertia
        ixx="0.0024453"
        ixy="1.2206E-06"
        ixz="-3.3328E-06"
        iyy="2.5397E-05"
        iyz="-5.4528E-06"
        izz="0.0024582" />
    </inertial>
    <visual>
      <origin
        xyz="0 0 0"
        rpy="0 0 0" />
      <geometry>
        <mesh
          filename="package://flypulator_description/meshes/arm_link_6.STL" />
      </geometry>
      <material
        name="">
        <color
          rgba="0.50196 0.50196 0.50196 1" />
      </material>
    </visual>
    <collision>
      <origin
        xyz="0 0 0"
        rpy="0 0 0" />
      <geometry>
        <mesh
          filename="package://flypulator_description/meshes/arm_link_6.STL" />
      </geometry>
    </collision>
  </link>
  <joint
    name="arm_joint_6"
    type="fixed">
    <origin
      xyz="-0.037928 -0.021878 0.03"
      rpy="-2.0233E-16 2.2195E-16 2.094" />
    <parent
      link="base_link" />
    <child
      link="arm_link_6" />
    <axis
      xyz="0 0 0" />
  </joint>
  <link
    name="motor_link_6">
    <inertial>
      <origin
        xyz="-0.0045936 0.018989 1.4274E-07"
        rpy="0 0 0" />
      <mass
        value="0.098041" />
      <inertia
        ixx="3.3229E-05"
        ixy="-2.523E-06"
        ixz="-8.3034E-10"
        iyy="4.3049E-05"
        iyz="4.9676E-11"
        izz="3.2621E-05" />
    </inertial>
    <visual>
      <origin
        xyz="0 0 0"
        rpy="0 0 0" />
      <geometry>
        <mesh
          filename="package://flypulator_description/meshes/motor_link_6.STL" />
      </geometry>
      <material
        name="">
        <color
          rgba="0.2 0.2 0.2 1" />
      </material>
    </visual>
    <collision>
      <origin
        xyz="0 0 0"
        rpy="0 0 0" />
      <geometry>
        <mesh
          filename="package://flypulator_description/meshes/motor_link_6.STL" />
      </geometry>
    </collision>
  </link>
  <joint
    name="motor_joint_6"
    type="fixed">
    <origin
      xyz="-0.001249 0.56231 0.0048421"
      rpy="1.5712 -1.6851E-16 -0.0017238" />
    <parent
      link="arm_link_6" />
    <child
      link="motor_link_6" />
    <axis
      xyz="0 0 0" />
  </joint>
  <link
    name="blade_link_6">
    <inertial>
      <origin
        xyz="3.3918E-06 -0.0016264 2.3978E-05"
        rpy="0 0 0" />
      <mass
        value="0.062747" />
      <inertia
        ixx="0.0014011"
        ixy="4.1612E-10"
        ixz="-6.2654E-06"
        iyy="0.0014075"
        iyz="1.6503E-09"
        izz="7.585E-06" />
    </inertial>
    <visual>
      <origin
        xyz="0 0 0"
        rpy="0 0 0" />
      <geometry>
        <mesh
          filename="package://flypulator_description/meshes/blade_link_6.STL" />
      </geometry>
      <material
        name="">
        <color
          rgba="0 0 0 1" />
      </material>
    </visual>
    <collision>
      <origin
        xyz="0 0 0"
        rpy="0 0 0" />
      <geometry>
        <mesh
          filename="package://flypulator_description/meshes/blade_link_6.STL" />
      </geometry>
    </collision>
  </link>
  <joint
    name="blade_joint_6"
    type="continuous">
    <origin
      xyz="-0.010817 0.04471 0"
      rpy="-3.1416 -0.0017735 -2.9042" />
    <parent
      link="motor_link_6" />
    <child
      link="blade_link_6" />
    <axis
      xyz="0 1 0" />
    <limit
      effort="0"
      velocity="630" />
  </joint>
</robot>
