<?xml version="1.0" ?>
<!-- =================================================================================== -->
<!-- |    This document was autogenerated by xacro from hexatilt_base.xacro            | -->
<!-- |    EDITING THIS FILE BY HAND IS NOT RECOMMENDED                                 | -->
<!-- =================================================================================== -->
<robot name="hexatilt" xmlns:xacro="http://ros.org/wiki/xacro">
  <gazebo>
    <plugin filename="libpropulsion_plugin.so" name="propulsion_plugin">
    </plugin>
  </gazebo>
  <!--<gazebo>
    <plugin name="control_plugin" filename="libcontrol_plugin.so">
    </plugin>
  </gazebo>-->
  <gazebo>
    <plugin filename="libfake_sensor_plugin.so" name="fake_sensor_plugin">
    </plugin>
  </gazebo>
  <gazebo>
    <plugin filename="libgazebo_ros_control.so" name="gazebo_ros_control">
      <robotNamespace>/drone</robotNamespace>
    </plugin>
  </gazebo>
  <gazebo>
    <plugin filename="libhector_gazebo_ros_imu.so" name="drone_internal_imu_plugin">
      <robotNamespace>/drone</robotNamespace>
      <alwaysOn>true</alwaysOn>
      <bodyName>base_link</bodyName>
      <frameName>base_link</frameName>
      <topicName>IMU/imu_data</topicName>
      <serviceName>drone/internal_sensors/imu_service</serviceName>
      <updateRate>100.0</updateRate>
      <gaussianNoise>0.001</gaussianNoise>
      <!-- accelerometer params -->
      <accelOffset>0.0 0.0 0.0</accelOffset>
      <accelGaussianNoise>0.0003 0.0003 0.0003</accelGaussianNoise>
      <accelDrift>0.00004 0.00004 0.00004</accelDrift>
      <accelFrequency>0.0025 0.0025 0.0025</accelFrequency>
      <!-- gyroscope params -->
      <rateOffset>0.0 0.0 0.0</rateOffset>
      <rateDrift>0.01 0.01 0.01</rateDrift>
      <rateDriftFrequency>0.001 0.001 0.001</rateDriftFrequency>
      <rateGaussianNoise>0.01 0.01 0.01</rateGaussianNoise>
    </plugin>
  </gazebo>
  <gazebo>
    <plugin filename="libhector_gazebo_ros_magnetic.so" name="drone_internal_magnetic_sim">
      <robotNamespace>/drone</robotNamespace>
      <updateRate>100.0</updateRate>
      <bodyName>base_link</bodyName>
      <frameId>base_link</frameId>
      <topicName>MAGNET/magnetic_data</topicName>
      <offset>0 0 0</offset>
      <drift>0.0 0.0 0.0</drift>
      <gaussianNoise>1.3e-3 1.3e-3 1.3e-3</gaussianNoise>
    </plugin>
  </gazebo>
  <gazebo>
    <plugin filename="libhector_gazebo_ros_gps.so" name="drone_internal_gps_sim">
      <robotNamespace>/drone</robotNamespace>
      <updateRate>4.0</updateRate>
      <bodyName>base_link</bodyName>
      <frameId>base_link</frameId>
      <topicName>GPS/fix</topicName>
      <velocityTopicName>GPS/fix_velocity</velocityTopicName>
      <referenceLatitude>49.860246</referenceLatitude>
      <referenceLongitude>8.687077</referenceLongitude>
      <drift>0.0 0.0 0.0</drift>
      <gaussianNoise>0.01 0.01 0.01</gaussianNoise>
      <velocityDrift>0 0 0</velocityDrift>
      <velocityGaussianNoise>0.01 0.01 0.01</velocityGaussianNoise>
    </plugin>
  </gazebo>
  <gazebo reference="base_link">
    <sensor name="camera1" type="camera">
      <update_rate>30.0</update_rate>
      <camera name="head">
        <vertical_fov>3.1415926</vertical_fov>
        <image>
          <width>800</width>
          <height>800</height>
          <format>R8G8B8</format>
        </image>
        <clip>
          <near>0.02</near>
          <far>300</far>
        </clip>
        <noise>
          <type>gaussian</type>
            --&gt;
          
          <!-- Noise is sampled independently per pixel on each frame.
               That pixel's noise value is added to each of its color
               channels, which at that point lie in the range [0,1]. -->
          <mean>0.0</mean>
          <stddev>0.007</stddev>
        </noise>
      </camera>
      <plugin filename="libgazebo_ros_camera.so" name="camera_controller">
        <robotNamespace>/drone</robotNamespace>
        <alwaysOn>true</alwaysOn>
        <updateRate>0.0</updateRate>
        <cameraName>camera1</cameraName>
        <imageTopicName>image_raw</imageTopicName>
        <cameraInfoTopicName>camera_info</cameraInfoTopicName>
        <frameName>base_link</frameName>
        <hackBaseline>0.07</hackBaseline>
        <distortionK1>0.0</distortionK1>
        <distortionK2>0.0</distortionK2>
        <distortionK3>0.0</distortionK3>
        <distortionT1>0.0</distortionT1>
        <distortionT2>0.0</distortionT2>
      </plugin>
    </sensor>
  </gazebo>
  <!-- [m] -->
  <link name="base_link"/>
  <joint name="base_joint" type="fixed">
    <origin rpy="0 0 0" xyz="0 0 0"/>
    <parent link="base_link"/>
    <child link="base_link_inertia"/>
  </joint>
  <link name="base_link_inertia">
    <inertial>
      <mass value="4.5"/>
      <!-- [kg] -->
      <origin xyz="0 0 0"/>
      <inertia ixx="0.0347563" ixy="0.0" ixz="0.0" iyy="0.0458929" iyz="0.0" izz="0.0977"/>
    </inertial>
    <visual>
      <origin rpy="0 0 0" xyz="0 0 0"/>
      <geometry>
        <mesh filename="package://hexatilt_description/meshes/hexatilt.dae" scale="0.001 0.001 0.001"/>
        <!-- <box size="${body_width} ${body_width} ${body_height}"/> -->
        <!-- [m] [m] [m] -->
      </geometry>
    </visual>
    <collision>
      <origin rpy="0 0 0" xyz="0 0 0"/>
      <geometry>
        <cylinder length="0.085" radius="0.45"/>
        <!-- [m] -->
        <!--box size="${body_width} ${body_width} ${body_height}" /-->
        <!-- [m] [m] [m] -->
      </geometry>
    </collision>
  </link>
  <!-- attach multirotor_base_plugin to the base_link -->
  <gazebo>
    <plugin filename="librotors_gazebo_multirotor_base_plugin.so" name="rosbag">
      <robotNamespace>hexatilt</robotNamespace>
      <linkName>base_link</linkName>
      <rotorVelocitySlowdownSim>10</rotorVelocitySlowdownSim>
    </plugin>
  </gazebo>
  <gazebo reference="base_link">
    <material>Gazebo/DarkGrey</material>
    <collision name="base_link_inertia_collision">
      <surface>
        <contact>
          <ode>
            <min_depth>0.001</min_depth>
            <max_vel>0.0</max_vel>
          </ode>
        </contact>
        <friction>
          <ode/>
        </friction>
      </surface>
    </collision>
  </gazebo>
  <joint name="rotor_0_joint" type="continuous">
    <origin rpy="0.2373645808 0  2.09439336" xyz="0.23 -0.37 0.06"/>
    <axis xyz="0 0 1"/>
    <!-- TODO(ff): not currently set because it's not yet supported -->
    <!-- <limit effort="2000" velocity="${max_rot_velocity}" /> -->
    <parent link="base_link"/>
    <child link="rotor_0"/>
  </joint>
  <!-- TODO(ff): not currently set because it's not yet supported -->
  <!-- <gazebo reference="rotor_${motor_number}_joint"> <axis> <xyz>0 0 1</xyz>
      <limit> <velocity> ${max_rot_velocity} </velocity> </limit> </axis> </gazebo> -->
  <link name="rotor_0">
    <inertial>
      <mass value="0.01"/>
      <!-- [kg] -->
      <inertia ixx="1.95e-06" ixy="0.0" ixz="0.0" iyy="0.00120975" iyz="0.0" izz="0.00121155"/>
    </inertial>
    <visual>
      <geometry>
        <!-- <cylinder length="0.005" radius="${radius_rotor}"/> -->
        <!-- [m] -->
        <mesh filename="package://hexatilt_description/meshes/hexatilt_prop_ccw.dae" scale="0.098 0.098 0.098"/>
        <!-- <box size="${2*radius_rotor} 0.01 0.005"/> -->
      </geometry>
    </visual>
    <collision>
      <geometry>
        <cylinder length="0.005" radius="0.1905"/>
        <!-- [m] -->
      </geometry>
    </collision>
  </link>
  <gazebo>
    <plugin filename="librotors_gazebo_motor_model.so" name="front_right_motor_model">
      <robotNamespace>hexatilt</robotNamespace>
      <jointName>rotor_0_joint</jointName>
      <linkName>rotor_0</linkName>
      <turningDirection>ccw</turningDirection>
      <timeConstantUp>0.0125</timeConstantUp>
      <timeConstantDown>0.025</timeConstantDown>
      <maxRotVelocity>1100</maxRotVelocity>
      <motorConstant>8.54858e-06</motorConstant>
      <momentConstant>0.06</momentConstant>
      <commandSubTopic>/gazebo/command/motor_speed</commandSubTopic>
      <motorNumber>0</motorNumber>
      <rotorDragCoefficient>0.000806428</rotorDragCoefficient>
      <rollingMomentCoefficient>1e-06</rollingMomentCoefficient>
      <motorSpeedPubTopic>/motor_speed/0</motorSpeedPubTopic>
      <rotorVelocitySlowdownSim>10</rotorVelocitySlowdownSim>
      <!--
        <gazebo_joint_control_pid>
          <p>0.1</p>
          <i>0</i>
          <d>0</d>
          <iMax>0</iMax>
          <iMin>0</iMin>
          <cmdMax>3</cmdMax>
          <cmdMin>-3</cmdMin>
        </gazebo_joint_control_pid>
      -->
    </plugin>
  </gazebo>
  <gazebo reference="rotor_0">
    <material>Gazebo/DarkGrey</material>
  </gazebo>
  <joint name="rotor_1_joint" type="continuous">
    <origin rpy="-0.2373645808 0  -1.04719668" xyz="-0.2 0.37 0.06"/>
    <axis xyz="0 0 1"/>
    <!-- TODO(ff): not currently set because it's not yet supported -->
    <!-- <limit effort="2000" velocity="${max_rot_velocity}" /> -->
    <parent link="base_link"/>
    <child link="rotor_1"/>
  </joint>
  <!-- TODO(ff): not currently set because it's not yet supported -->
  <!-- <gazebo reference="rotor_${motor_number}_joint"> <axis> <xyz>0 0 1</xyz>
      <limit> <velocity> ${max_rot_velocity} </velocity> </limit> </axis> </gazebo> -->
  <link name="rotor_1">
    <inertial>
      <mass value="0.01"/>
      <!-- [kg] -->
      <inertia ixx="1.95e-06" ixy="0.0" ixz="0.0" iyy="0.00120975" iyz="0.0" izz="0.00121155"/>
    </inertial>
    <visual>
      <geometry>
        <!-- <cylinder length="0.005" radius="${radius_rotor}"/> -->
        <!-- [m] -->
        <mesh filename="package://hexatilt_description/meshes/hexatilt_prop_ccw.dae" scale="0.098 0.098 0.098"/>
        <!-- <box size="${2*radius_rotor} 0.01 0.005"/> -->
      </geometry>
    </visual>
    <collision>
      <geometry>
        <cylinder length="0.005" radius="0.1905"/>
        <!-- [m] -->
      </geometry>
    </collision>
  </link>
  <gazebo>
    <plugin filename="librotors_gazebo_motor_model.so" name="back_left_motor_model">
      <robotNamespace>hexatilt</robotNamespace>
      <jointName>rotor_1_joint</jointName>
      <linkName>rotor_1</linkName>
      <turningDirection>ccw</turningDirection>
      <timeConstantUp>0.0125</timeConstantUp>
      <timeConstantDown>0.025</timeConstantDown>
      <maxRotVelocity>1100</maxRotVelocity>
      <motorConstant>8.54858e-06</motorConstant>
      <momentConstant>0.06</momentConstant>
      <commandSubTopic>/gazebo/command/motor_speed</commandSubTopic>
      <motorNumber>1</motorNumber>
      <rotorDragCoefficient>0.000806428</rotorDragCoefficient>
      <rollingMomentCoefficient>1e-06</rollingMomentCoefficient>
      <motorSpeedPubTopic>/motor_speed/1</motorSpeedPubTopic>
      <rotorVelocitySlowdownSim>10</rotorVelocitySlowdownSim>
      <!--
        <gazebo_joint_control_pid>
          <p>0.1</p>
          <i>0</i>
          <d>0</d>
          <iMax>0</iMax>
          <iMin>0</iMin>
          <cmdMax>3</cmdMax>
          <cmdMin>-3</cmdMin>
        </gazebo_joint_control_pid>
      -->
    </plugin>
  </gazebo>
  <gazebo reference="rotor_1">
    <material>Gazebo/Red</material>
  </gazebo>
  <joint name="rotor_2_joint" type="continuous">
    <origin rpy="0.2373645808 0  4.18878672" xyz="0.2 0.37 0.06"/>
    <axis xyz="0 0 1"/>
    <!-- TODO(ff): not currently set because it's not yet supported -->
    <!-- <limit effort="2000" velocity="${max_rot_velocity}" /> -->
    <parent link="base_link"/>
    <child link="rotor_2"/>
  </joint>
  <!-- TODO(ff): not currently set because it's not yet supported -->
  <!-- <gazebo reference="rotor_${motor_number}_joint"> <axis> <xyz>0 0 1</xyz>
      <limit> <velocity> ${max_rot_velocity} </velocity> </limit> </axis> </gazebo> -->
  <link name="rotor_2">
    <inertial>
      <mass value="0.01"/>
      <!-- [kg] -->
      <inertia ixx="1.95e-06" ixy="0.0" ixz="0.0" iyy="0.00120975" iyz="0.0" izz="0.00121155"/>
    </inertial>
    <visual>
      <geometry>
        <!-- <cylinder length="0.005" radius="${radius_rotor}"/> -->
        <!-- [m] -->
        <mesh filename="package://hexatilt_description/meshes/hexatilt_prop_cw.dae" scale="0.098 0.098 0.098"/>
        <!-- <box size="${2*radius_rotor} 0.01 0.005"/> -->
      </geometry>
    </visual>
    <collision>
      <geometry>
        <cylinder length="0.005" radius="0.1905"/>
        <!-- [m] -->
      </geometry>
    </collision>
  </link>
  <gazebo>
    <plugin filename="librotors_gazebo_motor_model.so" name="front_left_motor_model">
      <robotNamespace>hexatilt</robotNamespace>
      <jointName>rotor_2_joint</jointName>
      <linkName>rotor_2</linkName>
      <turningDirection>cw</turningDirection>
      <timeConstantUp>0.0125</timeConstantUp>
      <timeConstantDown>0.025</timeConstantDown>
      <maxRotVelocity>1100</maxRotVelocity>
      <motorConstant>8.54858e-06</motorConstant>
      <momentConstant>0.06</momentConstant>
      <commandSubTopic>/gazebo/command/motor_speed</commandSubTopic>
      <motorNumber>2</motorNumber>
      <rotorDragCoefficient>0.000806428</rotorDragCoefficient>
      <rollingMomentCoefficient>1e-06</rollingMomentCoefficient>
      <motorSpeedPubTopic>/motor_speed/2</motorSpeedPubTopic>
      <rotorVelocitySlowdownSim>10</rotorVelocitySlowdownSim>
      <!--
        <gazebo_joint_control_pid>
          <p>0.1</p>
          <i>0</i>
          <d>0</d>
          <iMax>0</iMax>
          <iMin>0</iMin>
          <cmdMax>3</cmdMax>
          <cmdMin>-3</cmdMin>
        </gazebo_joint_control_pid>
      -->
    </plugin>
  </gazebo>
  <gazebo reference="rotor_2">
    <material>Gazebo/Red</material>
  </gazebo>
  <joint name="rotor_3_joint" type="continuous">
    <origin rpy="-0.2373645808 0  1.04719668" xyz="-0.23 -0.37 0.06"/>
    <axis xyz="0 0 1"/>
    <!-- TODO(ff): not currently set because it's not yet supported -->
    <!-- <limit effort="2000" velocity="${max_rot_velocity}" /> -->
    <parent link="base_link"/>
    <child link="rotor_3"/>
  </joint>
  <!-- TODO(ff): not currently set because it's not yet supported -->
  <!-- <gazebo reference="rotor_${motor_number}_joint"> <axis> <xyz>0 0 1</xyz>
      <limit> <velocity> ${max_rot_velocity} </velocity> </limit> </axis> </gazebo> -->
  <link name="rotor_3">
    <inertial>
      <mass value="0.01"/>
      <!-- [kg] -->
      <inertia ixx="1.95e-06" ixy="0.0" ixz="0.0" iyy="0.00120975" iyz="0.0" izz="0.00121155"/>
    </inertial>
    <visual>
      <geometry>
        <!-- <cylinder length="0.005" radius="${radius_rotor}"/> -->
        <!-- [m] -->
        <mesh filename="package://hexatilt_description/meshes/hexatilt_prop_cw.dae" scale="0.098 0.098 0.098"/>
        <!-- <box size="${2*radius_rotor} 0.01 0.005"/> -->
      </geometry>
    </visual>
    <collision>
      <geometry>
        <cylinder length="0.005" radius="0.1905"/>
        <!-- [m] -->
      </geometry>
    </collision>
  </link>
  <gazebo>
    <plugin filename="librotors_gazebo_motor_model.so" name="back_right_motor_model">
      <robotNamespace>hexatilt</robotNamespace>
      <jointName>rotor_3_joint</jointName>
      <linkName>rotor_3</linkName>
      <turningDirection>cw</turningDirection>
      <timeConstantUp>0.0125</timeConstantUp>
      <timeConstantDown>0.025</timeConstantDown>
      <maxRotVelocity>1100</maxRotVelocity>
      <motorConstant>8.54858e-06</motorConstant>
      <momentConstant>0.06</momentConstant>
      <commandSubTopic>/gazebo/command/motor_speed</commandSubTopic>
      <motorNumber>3</motorNumber>
      <rotorDragCoefficient>0.000806428</rotorDragCoefficient>
      <rollingMomentCoefficient>1e-06</rollingMomentCoefficient>
      <motorSpeedPubTopic>/motor_speed/3</motorSpeedPubTopic>
      <rotorVelocitySlowdownSim>10</rotorVelocitySlowdownSim>
      <!--
        <gazebo_joint_control_pid>
          <p>0.1</p>
          <i>0</i>
          <d>0</d>
          <iMax>0</iMax>
          <iMin>0</iMin>
          <cmdMax>3</cmdMax>
          <cmdMin>-3</cmdMin>
        </gazebo_joint_control_pid>
      -->
    </plugin>
  </gazebo>
  <gazebo reference="rotor_3">
    <material>Gazebo/DarkGrey</material>
  </gazebo>
  <joint name="rotor_4_joint" type="continuous">
    <origin rpy="0.2373645808 0  0.0" xyz="-0.43 -0.01 0.06"/>
    <axis xyz="0 0 1"/>
    <!-- TODO(ff): not currently set because it's not yet supported -->
    <!-- <limit effort="2000" velocity="${max_rot_velocity}" /> -->
    <parent link="base_link"/>
    <child link="rotor_4"/>
  </joint>
  <!-- TODO(ff): not currently set because it's not yet supported -->
  <!-- <gazebo reference="rotor_${motor_number}_joint"> <axis> <xyz>0 0 1</xyz>
      <limit> <velocity> ${max_rot_velocity} </velocity> </limit> </axis> </gazebo> -->
  <link name="rotor_4">
    <inertial>
      <mass value="0.01"/>
      <!-- [kg] -->
      <inertia ixx="1.95e-06" ixy="0.0" ixz="0.0" iyy="0.00120975" iyz="0.0" izz="0.00121155"/>
    </inertial>
    <visual>
      <geometry>
        <!-- <cylinder length="0.005" radius="${radius_rotor}"/> -->
        <!-- [m] -->
        <mesh filename="package://hexatilt_description/meshes/hexatilt_prop_cw.dae" scale="0.098 0.098 0.098"/>
        <!-- <box size="${2*radius_rotor} 0.01 0.005"/> -->
      </geometry>
    </visual>
    <collision>
      <geometry>
        <cylinder length="0.005" radius="0.1905"/>
        <!-- [m] -->
      </geometry>
    </collision>
  </link>
  <gazebo>
    <plugin filename="librotors_gazebo_motor_model.so" name="back_right_motor_model">
      <robotNamespace>hexatilt</robotNamespace>
      <jointName>rotor_4_joint</jointName>
      <linkName>rotor_4</linkName>
      <turningDirection>cw</turningDirection>
      <timeConstantUp>0.0125</timeConstantUp>
      <timeConstantDown>0.025</timeConstantDown>
      <maxRotVelocity>1100</maxRotVelocity>
      <motorConstant>8.54858e-06</motorConstant>
      <momentConstant>0.06</momentConstant>
      <commandSubTopic>/gazebo/command/motor_speed</commandSubTopic>
      <motorNumber>4</motorNumber>
      <rotorDragCoefficient>0.000806428</rotorDragCoefficient>
      <rollingMomentCoefficient>1e-06</rollingMomentCoefficient>
      <motorSpeedPubTopic>/motor_speed/4</motorSpeedPubTopic>
      <rotorVelocitySlowdownSim>10</rotorVelocitySlowdownSim>
      <!--
        <gazebo_joint_control_pid>
          <p>0.1</p>
          <i>0</i>
          <d>0</d>
          <iMax>0</iMax>
          <iMin>0</iMin>
          <cmdMax>3</cmdMax>
          <cmdMin>-3</cmdMin>
        </gazebo_joint_control_pid>
      -->
    </plugin>
  </gazebo>
  <gazebo reference="rotor_4">
    <material>Gazebo/DarkGrey</material>
  </gazebo>
  <joint name="rotor_5_joint" type="continuous">
    <origin rpy="-0.2373645808 0  3.14159004" xyz="0.43 -0.01 0.06"/>
    <axis xyz="0 0 1"/>
    <!-- TODO(ff): not currently set because it's not yet supported -->
    <!-- <limit effort="2000" velocity="${max_rot_velocity}" /> -->
    <parent link="base_link"/>
    <child link="rotor_5"/>
  </joint>
  <!-- TODO(ff): not currently set because it's not yet supported -->
  <!-- <gazebo reference="rotor_${motor_number}_joint"> <axis> <xyz>0 0 1</xyz>
      <limit> <velocity> ${max_rot_velocity} </velocity> </limit> </axis> </gazebo> -->
  <link name="rotor_5">
    <inertial>
      <mass value="0.01"/>
      <!-- [kg] -->
      <inertia ixx="1.95e-06" ixy="0.0" ixz="0.0" iyy="0.00120975" iyz="0.0" izz="0.00121155"/>
    </inertial>
    <visual>
      <geometry>
        <!-- <cylinder length="0.005" radius="${radius_rotor}"/> -->
        <!-- [m] -->
        <mesh filename="package://hexatilt_description/meshes/hexatilt_prop_cw.dae" scale="0.098 0.098 0.098"/>
        <!-- <box size="${2*radius_rotor} 0.01 0.005"/> -->
      </geometry>
    </visual>
    <collision>
      <geometry>
        <cylinder length="0.005" radius="0.1905"/>
        <!-- [m] -->
      </geometry>
    </collision>
  </link>
  <gazebo>
    <plugin filename="librotors_gazebo_motor_model.so" name="back_right_motor_model">
      <robotNamespace>hexatilt</robotNamespace>
      <jointName>rotor_5_joint</jointName>
      <linkName>rotor_5</linkName>
      <turningDirection>cw</turningDirection>
      <timeConstantUp>0.0125</timeConstantUp>
      <timeConstantDown>0.025</timeConstantDown>
      <maxRotVelocity>1100</maxRotVelocity>
      <motorConstant>8.54858e-06</motorConstant>
      <momentConstant>0.06</momentConstant>
      <commandSubTopic>/gazebo/command/motor_speed</commandSubTopic>
      <motorNumber>5</motorNumber>
      <rotorDragCoefficient>0.000806428</rotorDragCoefficient>
      <rollingMomentCoefficient>1e-06</rollingMomentCoefficient>
      <motorSpeedPubTopic>/motor_speed/5</motorSpeedPubTopic>
      <rotorVelocitySlowdownSim>10</rotorVelocitySlowdownSim>
      <!--
        <gazebo_joint_control_pid>
          <p>0.1</p>
          <i>0</i>
          <d>0</d>
          <iMax>0</iMax>
          <iMin>0</iMin>
          <cmdMax>3</cmdMax>
          <cmdMin>-3</cmdMin>
        </gazebo_joint_control_pid>
      -->
    </plugin>
  </gazebo>
  <gazebo reference="rotor_5">
    <material>Gazebo/DarkGrey</material>
  </gazebo>
  <!-- Landing gear joint: -->
  <joint name="leg_1_joint" type="revolute">
    <origin rpy="0 0 0" xyz="0.11 0 -0.02"/>
    <axis xyz="0 1 0"/>
    <!-- TODO(ff): not currently set because it's not yet supported -->
    <!-- <limit effort="2000" velocity="${max_rot_velocity}" /> -->
    <limit effort="0" lower="-0.1745" upper="-1.5705" velocity="0"/>
    <parent link="base_link"/>
    <child link="leg_1"/>
  </joint>
  <!-- Leg link -->
  <link name="leg_1">
    <inertial>
      <origin rpy="0 0 0 " xyz="0 0 -0.2065"/>
      <mass value="0.18"/>
      <!-- [kg] -->
      <inertia ixx="1.95e-06" ixy="0.0" ixz="0.0" iyy="0.00120975" iyz="0.0" izz="0.00121155"/>
    </inertial>
    <visual>
      <origin rpy="0 0 0 " xyz="0 0 0"/>
      <geometry>
        <!-- <cylinder length="0.005" radius="${radius_rotor}"/> -->
        <!-- [m] -->
        <mesh filename="package://hexatilt_description/meshes/right_leg.dae" scale="0.1 0.1 0.1"/>
        <!-- <cylinder length="${length_leg}" radius="${radius_leg}" /> <1 [m] -1> -->
      </geometry>
    </visual>
    <collision>
      <origin rpy="0 0 0 " xyz="0 0 -0.2065"/>
      <geometry>
        <cylinder length="0.413" radius="0.0125"/>
        <!-- [m] -->
      </geometry>
    </collision>
  </link>
  <!-- Joint Leg-foot fixed -->
  <joint name="foot_1_joint" type="fixed">
    <parent link="leg_1"/>
    <child link="foot_1"/>
    <origin rpy="1.57 0 0" xyz="0 0 -0.413"/>
  </joint>
  <!-- Foot link -->
  <link name="foot_1">
    <inertial>
      <mass value="0.18"/>
      <!-- [kg] -->
      <inertia ixx="1.95e-06" ixy="0.0" ixz="0.0" iyy="0.00120975" iyz="0.0" izz="0.00121155"/>
    </inertial>
    <!-- <visual> -->
    <!-- <geometry> -->
    <!-- <cylinder length="0.005" radius="${radius_rotor}"/> -->
    <!-- [m] -->
    <!-- <mesh filename="package://hexatilt_description/meshes/${mesh}_${suffix}.dae" -->
    <!-- scale="${mesh_scale}" /> -->
    <!-- <cylinder length="${length_leg}" radius="${radius_leg}" />  -->
    <!-- </geometry> -->
    <!-- </visual> -->
    <collision>
      <geometry>
        <cylinder length="0.413" radius="0.0125"/>
        <!-- [m] -->
      </geometry>
    </collision>
  </link>
  <gazebo>
    <!-- <plugin name="${suffix}_leg_model" filename="librotors_gazebo_leg_model.so"> -->
    <!-- <robotNamespace>${robot_namespace}</robotNamespace> -->
    <!-- <jointName>rotor_${leg_number}_joint</jointName> -->
    <!-- <linkName>rotor_${leg_number}</linkName> -->
    <!-- <turningDirection>${direction}</turningDirection> -->
    <!-- <timeConstantUp>${time_constant_up}</timeConstantUp> -->
    <!-- <timeConstantDown>${time_constant_down}</timeConstantDown> -->
    <!-- <maxRotVelocity>${max_rot_velocity}</maxRotVelocity> -->
    <!-- <legConstant>${leg_constant}</legConstant> -->
    <!-- <momentConstant>${moment_constant}</momentConstant> -->
    <!-- <commandSubTopic>/gazebo/command/leg_speed</commandSubTopic> -->
    <!-- <legNumber>${leg_number}</legNumber> -->
    <!-- <rotorDragCoefficient>${rotor_drag_coefficient}</rotorDragCoefficient> -->
    <!-- <rollingMomentCoefficient>${rolling_moment_coefficient}</rollingMomentCoefficient> -->
    <!-- <motorSpeedPubTopic>/motor_speed/${leg_number}</motorSpeedPubTopic> -->
    <!-- <rotorVelocitySlowdownSim>${rotor_velocity_slowdown_sim}</rotorVelocitySlowdownSim> -->
    <!--
        <gazebo_joint_control_pid>
          <p>0.1</p>
          <i>0</i>
          <d>0</d>
          <iMax>0</iMax>
          <iMin>0</iMin>
          <cmdMax>3</cmdMax>
          <cmdMin>-3</cmdMin>
        </gazebo_joint_control_pid>
      -->
    <!-- </plugin> -->
  </gazebo>
  <gazebo reference="leg_1">
    <material>Gazebo/DarkGrey</material>
  </gazebo>
  <!-- Landing gear joint: -->
  <joint name="leg_2_joint" type="revolute">
    <origin rpy="0 0 0" xyz="-0.11 0 -0.02"/>
    <axis xyz="0 1 0"/>
    <!-- TODO(ff): not currently set because it's not yet supported -->
    <!-- <limit effort="2000" velocity="${max_rot_velocity}" /> -->
    <limit effort="0" lower="0.1745" upper="1.5705" velocity="0"/>
    <parent link="base_link"/>
    <child link="leg_2"/>
  </joint>
  <!-- Leg link -->
  <link name="leg_2">
    <inertial>
      <origin rpy="0 0 0 " xyz="0 0 -0.2065"/>
      <mass value="0.18"/>
      <!-- [kg] -->
      <inertia ixx="1.95e-06" ixy="0.0" ixz="0.0" iyy="0.00120975" iyz="0.0" izz="0.00121155"/>
    </inertial>
    <visual>
      <origin rpy="0 0 0 " xyz="0 0 0"/>
      <geometry>
        <!-- <cylinder length="0.005" radius="${radius_rotor}"/> -->
        <!-- [m] -->
        <mesh filename="package://hexatilt_description/meshes/right_leg.dae" scale="0.1 0.1 0.1"/>
        <!-- <cylinder length="${length_leg}" radius="${radius_leg}" /> <1 [m] -1> -->
      </geometry>
    </visual>
    <collision>
      <origin rpy="0 0 0 " xyz="0 0 -0.2065"/>
      <geometry>
        <cylinder length="0.413" radius="0.0125"/>
        <!-- [m] -->
      </geometry>
    </collision>
  </link>
  <!-- Joint Leg-foot fixed -->
  <joint name="foot_2_joint" type="fixed">
    <parent link="leg_2"/>
    <child link="foot_2"/>
    <origin rpy="1.57 0 0" xyz="0 0 -0.413"/>
  </joint>
  <!-- Foot link -->
  <link name="foot_2">
    <inertial>
      <mass value="0.18"/>
      <!-- [kg] -->
      <inertia ixx="1.95e-06" ixy="0.0" ixz="0.0" iyy="0.00120975" iyz="0.0" izz="0.00121155"/>
    </inertial>
    <!-- <visual> -->
    <!-- <geometry> -->
    <!-- <cylinder length="0.005" radius="${radius_rotor}"/> -->
    <!-- [m] -->
    <!-- <mesh filename="package://hexatilt_description/meshes/${mesh}_${suffix}.dae" -->
    <!-- scale="${mesh_scale}" /> -->
    <!-- <cylinder length="${length_leg}" radius="${radius_leg}" />  -->
    <!-- </geometry> -->
    <!-- </visual> -->
    <collision>
      <geometry>
        <cylinder length="0.413" radius="0.0125"/>
        <!-- [m] -->
      </geometry>
    </collision>
  </link>
  <gazebo>
    <!-- <plugin name="${suffix}_leg_model" filename="librotors_gazebo_leg_model.so"> -->
    <!-- <robotNamespace>${robot_namespace}</robotNamespace> -->
    <!-- <jointName>rotor_${leg_number}_joint</jointName> -->
    <!-- <linkName>rotor_${leg_number}</linkName> -->
    <!-- <turningDirection>${direction}</turningDirection> -->
    <!-- <timeConstantUp>${time_constant_up}</timeConstantUp> -->
    <!-- <timeConstantDown>${time_constant_down}</timeConstantDown> -->
    <!-- <maxRotVelocity>${max_rot_velocity}</maxRotVelocity> -->
    <!-- <legConstant>${leg_constant}</legConstant> -->
    <!-- <momentConstant>${moment_constant}</momentConstant> -->
    <!-- <commandSubTopic>/gazebo/command/leg_speed</commandSubTopic> -->
    <!-- <legNumber>${leg_number}</legNumber> -->
    <!-- <rotorDragCoefficient>${rotor_drag_coefficient}</rotorDragCoefficient> -->
    <!-- <rollingMomentCoefficient>${rolling_moment_coefficient}</rollingMomentCoefficient> -->
    <!-- <motorSpeedPubTopic>/motor_speed/${leg_number}</motorSpeedPubTopic> -->
    <!-- <rotorVelocitySlowdownSim>${rotor_velocity_slowdown_sim}</rotorVelocitySlowdownSim> -->
    <!--
        <gazebo_joint_control_pid>
          <p>0.1</p>
          <i>0</i>
          <d>0</d>
          <iMax>0</iMax>
          <iMin>0</iMin>
          <cmdMax>3</cmdMax>
          <cmdMin>-3</cmdMin>
        </gazebo_joint_control_pid>
      -->
    <!-- </plugin> -->
  </gazebo>
  <gazebo reference="leg_2">
    <material>Gazebo/DarkGrey</material>
  </gazebo>
  <gazebo>
    <plugin filename="libgazebo_gps_plugin.so" name="gps_plugin">
      <robotNamespace>hexatilt</robotNamespace>
      <gpsNoise>true</gpsNoise>
    </plugin>
  </gazebo>
</robot>

